Workbook

Sheet CSP Sum
B2: UCO BC AGENT BUSINESS SUMMARY
B3: Code | C3: CSP Name | G3: Branch Name | K3: ZO Name | M3: DC Name | P3: Age of CSP | Q3: Overall Performance
C4: =IFERROR(VLOOKUP($B$4,Data!$A:$J,6,0),"") | G4: =IFERROR(VLOOKUP($B$4,Data!$A:$G,5,0),"") | K4: =IFERROR(VLOOKUP($B$4,Data!$A:$G,4,0),"") | M4: =IFERROR(VLOOKUP($B$4,Data!$A:$G,2,0),"") | P4: =IFERROR(VLOOKUP($B$4,Data!$A:$J,10,0),"") | Q4: =IF(U4>=90%,"Outstanding",IF(U4>=80%,"Excellent",IF(U4>=70%,"Very Good",IF(U4>=60%,"Good",IF(U4>=50%,"Average",IF(U4>=40%,"Below Average",IF(U4>=30%,"Poor",IF(U4>=20%,"Very Poor",IF(U4<=20%,"Not Satisfactory"))))))))) -> Not Satisfactory | U4: =AVERAGE(S8,S9,S10) -> 0
B5: FY 2026-27 (Report till 06-09-2026)
B6: Category | C6: 46113 | D6: 46143 | E6: 46174 | F6: 46204 | G6: 46235 | H6: 46266 | I6: 46296 | J6: 46327 | K6: 46357 | L6: 46388 | M6: 46419 | N6: 46447 | O6: Total | P6: Average | Q6: Target | R6: Gap | S6: % | T6: Performance
B7: PMJDY AC | C7: =IFERROR(VLOOKUP($B$4,AC!$G:$W,4,0),"") | D7: =IFERROR(VLOOKUP($B$4,AC!$G:$W,5,0),"") | E7: =IFERROR(VLOOKUP($B$4,AC!$G:$W,6,0),"") | F7: =IFERROR(VLOOKUP($B$4,AC!$G:$W,7,0),"") | G7: =IFERROR(VLOOKUP($B$4,AC!$G:$W,8,0),"") | H7: =IFERROR(VLOOKUP($B$4,AC!$G:$W,9,0),"") | I7: =IFERROR(VLOOKUP($B$4,AC!$G:$W,10,0),"") | J7: =IFERROR(VLOOKUP($B$4,AC!$G:$W,11,0),"") | K7: =IFERROR(VLOOKUP($B$4,AC!$G:$W,12,0),"") | L7: =IFERROR(VLOOKUP($B$4,AC!$G:$W,13,0),"") | M7: =IFERROR(VLOOKUP($B$4,AC!$G:$W,14,0),"") | N7: =IFERROR(VLOOKUP($B$4,AC!$G:$W,15,0),"") | O7: =SUM(C7:N7) -> 0 | P7: =O7/$P$15 -> 0 | Q7: =$P$15*30 -> 30 | R7: =Q7-O7 -> 30 | S7: =O7/($P$15*30) -> 0 | T7: =IF(S7>=90%,"Outstanding",IF(S7>=80%,"Excellent",IF(S7>=70%,"Very Good",IF(S7>=60%,"Good",IF(S7>=50%,"Average",IF(S7>=40%,"Below Average",IF(S7>=30%,"Poor",IF(S7>=20%,"Very Poor",IF(S7<=20%,"Not Satisfactory"))))))))) -> Not Satisfactory
B8: APY | C8: =IFERROR(VLOOKUP($B$4,APY!$G:$X,5,0),"") | D8: =IFERROR(VLOOKUP($B$4,APY!$G:$X,6,0),"") | E8: =IFERROR(VLOOKUP($B$4,APY!$G:$X,7,0),"") | F8: =IFERROR(VLOOKUP($B$4,APY!$G:$X,8,0),"") | G8: =IFERROR(VLOOKUP($B$4,APY!$G:$X,9,0),"") | H8: =IFERROR(VLOOKUP($B$4,APY!$G:$X,10,0),"") | I8: =IFERROR(VLOOKUP($B$4,APY!$G:$X,11,0),"") | J8: =IFERROR(VLOOKUP($B$4,APY!$G:$X,12,0),"") | K8: =IFERROR(VLOOKUP($B$4,APY!$G:$X,13,0),"") | L8: =IFERROR(VLOOKUP($B$4,APY!$G:$X,14,0),"") | M8: =IFERROR(VLOOKUP($B$4,APY!$G:$X,15,0),"") | N8: =IFERROR(VLOOKUP($B$4,APY!$G:$X,16,0),"") | O8: =SUM(C8:N8) -> 0 | P8: =O8/$P$15 -> 0 | Q8: =$P$15*15 -> 15 | R8: =Q8-O8 -> 15 | S8: =O8/($P$15*15) -> 0 | T8: =IF(S8>=90%,"Outstanding",IF(S8>=80%,"Excellent",IF(S8>=70%,"Very Good",IF(S8>=60%,"Good",IF(S8>=50%,"Average",IF(S8>=40%,"Below Average",IF(S8>=30%,"Poor",IF(S8>=20%,"Very Poor",IF(S8<=20%,"Not Satisfactory"))))))))) -> Not Satisfactory
B9: PMJJBY | C9: =IFERROR(VLOOKUP($B$4,JJBY!$G:$X,5,0),"") | D9: =IFERROR(VLOOKUP($B$4,JJBY!$G:$X,6,0),"") | E9: =IFERROR(VLOOKUP($B$4,JJBY!$G:$X,7,0),"") | F9: =IFERROR(VLOOKUP($B$4,JJBY!$G:$X,8,0),"") | G9: =IFERROR(VLOOKUP($B$4,JJBY!$G:$X,9,0),"") | H9: =IFERROR(VLOOKUP($B$4,JJBY!$G:$X,10,0),"") | I9: =IFERROR(VLOOKUP($B$4,JJBY!$G:$X,11,0),"") | J9: =IFERROR(VLOOKUP($B$4,JJBY!$G:$X,12,0),"") | K9: =IFERROR(VLOOKUP($B$4,JJBY!$G:$X,13,0),"") | L9: =IFERROR(VLOOKUP($B$4,JJBY!$G:$X,14,0),"") | M9: =IFERROR(VLOOKUP($B$4,JJBY!$G:$X,15,0),"") | N9: =IFERROR(VLOOKUP($B$4,JJBY!$G:$X,16,0),"") | O9: =SUM(C9:N9) -> 0 | P9: =O9/$P$15 -> 0 | Q9: =$P$15*12 -> 12 | R9: =Q9-O9 -> 12 | S9: =O9/($P$15*12) -> 0 | T9: =IF(S9>=90%,"Outstanding",IF(S9>=80%,"Excellent",IF(S9>=70%,"Very Good",IF(S9>=60%,"Good",IF(S9>=50%,"Average",IF(S9>=40%,"Below Average",IF(S9>=30%,"Poor",IF(S9>=20%,"Very Poor",IF(S9<=20%,"Not Satisfactory"))))))))) -> Not Satisfactory
B10: PMSBY | C10: =IFERROR(VLOOKUP($B$4,SBY!$G:$X,5,0),"") | D10: =IFERROR(VLOOKUP($B$4,SBY!$G:$X,6,0),"") | E10: =IFERROR(VLOOKUP($B$4,SBY!$G:$X,7,0),"") | F10: =IFERROR(VLOOKUP($B$4,SBY!$G:$X,8,0),"") | G10: =IFERROR(VLOOKUP($B$4,SBY!$G:$X,9,0),"") | H10: =IFERROR(VLOOKUP($B$4,SBY!$G:$X,10,0),"") | I10: =IFERROR(VLOOKUP($B$4,SBY!$G:$X,11,0),"") | J10: =IFERROR(VLOOKUP($B$4,SBY!$G:$X,12,0),"") | K10: =IFERROR(VLOOKUP($B$4,SBY!$G:$X,13,0),"") | L10: =IFERROR(VLOOKUP($B$4,SBY!$G:$X,14,0),"") | M10: =IFERROR(VLOOKUP($B$4,SBY!$G:$X,15,0),"") | N10: =IFERROR(VLOOKUP($B$4,SBY!$G:$X,16,0),"") | O10: =SUM(C10:N10) -> 0 | P10: =O10/$P$15 -> 0 | Q10: =$P$15*24 -> 24 | R10: =Q10-O10 -> 24 | S10: =O10/($P$15*24) -> 0 | T10: =IF(S10>=90%,"Outstanding",IF(S10>=80%,"Excellent",IF(S10>=70%,"Very Good",IF(S10>=60%,"Good",IF(S10>=50%,"Average",IF(S10>=40%,"Below Average",IF(S10>=30%,"Poor",IF(S10>=20%,"Very Poor",IF(S10<=20%,"Not Satisfactory"))))))))) -> Not Satisfactory
B11: Daily LogIn | C11: =IFERROR(VLOOKUP($B$4,Log!$G:$W,4,0),"") | D11: =IFERROR(VLOOKUP($B$4,Log!$G:$W,5,0),"") | E11: =IFERROR(VLOOKUP($B$4,Log!$G:$W,6,0),"") | F11: =IFERROR(VLOOKUP($B$4,Log!$G:$W,7,0),"") | G11: =IFERROR(VLOOKUP($B$4,Log!$G:$W,8,0),"") | H11: =IFERROR(VLOOKUP($B$4,Log!$G:$W,9,0),"") | I11: =IFERROR(VLOOKUP($B$4,Log!$G:$W,10,0),"") | J11: =IFERROR(VLOOKUP($B$4,Log!$G:$W,11,0),"") | K11: =IFERROR(VLOOKUP($B$4,Log!$G:$W,12,0),"") | L11: =IFERROR(VLOOKUP($B$4,Log!$G:$W,13,0),"") | M11: =IFERROR(VLOOKUP($B$4,Log!$G:$W,14,0),"") | N11: =IFERROR(VLOOKUP($B$4,Log!$G:$W,15,0),"") | O11: =SUM(C11:N11) -> 0 | P11: =O11/$P$15 -> 0 | Q11: Monthly Target: AC -30, APY - 15, PMJJBY - 12, PMSBY - 24
B12: Transaction | C12: =IFERROR(VLOOKUP($B$4,'FI txn'!$G:$X,4,0),"") | D12: =IFERROR(VLOOKUP($B$4,'FI txn'!$G:$X,5,0),"") | E12: =IFERROR(VLOOKUP($B$4,'FI txn'!$G:$X,6,0),"") | F12: =IFERROR(VLOOKUP($B$4,'FI txn'!$G:$X,7,0),"") | G12: =IFERROR(VLOOKUP($B$4,'FI txn'!$G:$X,8,0),"") | H12: =IFERROR(VLOOKUP($B$4,'FI txn'!$G:$X,9,0),"") | I12: =IFERROR(VLOOKUP($B$4,'FI txn'!$G:$X,10,0),"") | J12: =IFERROR(VLOOKUP($B$4,'FI txn'!$G:$X,11,0),"") | K12: =IFERROR(VLOOKUP($B$4,'FI txn'!$G:$X,12,0),"") | L12: =IFERROR(VLOOKUP($B$4,'FI txn'!$G:$X,13,0),"") | M12: =IFERROR(VLOOKUP($B$4,'FI txn'!$G:$X,14,0),"") | N12: =IFERROR(VLOOKUP($B$4,'FI txn'!$G:$X,15,0),"") | O12: =SUM(C12:N12) -> 0 | P12: =O12/$P$15 -> 0
B13: Commission | C13: =IFERROR(C15*80%,"") | D13: =IFERROR(D15*80%,"") | E13: =IFERROR(E15*80%,"") | F13: =IFERROR(F15*80%,"") | G13: =IFERROR(G15*80%,"") | H13: =IFERROR(H15*80%,"") | I13: =IFERROR(I15*80%,"") | J13: =IFERROR(J15*80%,"") | ... N13: =IFERROR(N15*80%,"") | O13: =SUM(C13:N13) -> 0 | P13: =IFERROR(O13/($P$15-1),"")
B15: Commission | C15: =IFERROR(VLOOKUP($B$4,Comm!$G:$W,4,0),"") | D15: =IFERROR(VLOOKUP($B$4,Comm!$G:$W,5,0),"") | E15: =IFERROR(VLOOKUP($B$4,Comm!$G:$W,6,0),"") | F15: =IFERROR(VLOOKUP($B$4,Comm!$G:$W,7,0),"") | G15: =IFERROR(VLOOKUP($B$4,Comm!$G:$W,8,0),"") | H15: =IFERROR(VLOOKUP($B$4,Comm!$G:$W,9,0),"") | I15: =IFERROR(VLOOKUP($B$4,Comm!$G:$W,10,0),"") | J15: =IFERROR(VLOOKUP($B$4,Comm!$G:$W,11,0),"") | K15: =IFERROR(VLOOKUP($B$4,Comm!$G:$W,12,0),"") | L15: =IFERROR(VLOOKUP($B$4,Comm!$G:$W,13,0),"") | M15: =IFERROR(VLOOKUP($B$4,Comm!$G:$W,14,0),"") | N15: =IFERROR(VLOOKUP($B$4,Comm!$G:$W,15,0),"") | O15: =SUM(C15:N15) -> 0 | P15: =COUNTIF(C15:N15,">0")+1 -> 1
B16: FY 2025-26
B17: Category | C17: 45748 | D17: 45778 | E17: 45809 | F17: 45839 | G17: 45870 | H17: 45901 | I17: 45931 | J17: 45962 | K17: 45992 | L17: 46023 | M17: 46054 | N17: 46082 | O17: Total | P17: Average | Q17: Target | R17: Gap | S17: % | T17: Performance
B18: PMJDY AC | C18: =IFERROR(VLOOKUP($B$4,[1]EKYC!$E:$W,5,0),"") | D18: =IFERROR(VLOOKUP($B$4,[1]EKYC!$E:$W,6,0),"") | E18: =IFERROR(VLOOKUP($B$4,[1]EKYC!$E:$W,7,0),"") | F18: =IFERROR(VLOOKUP($B$4,[1]EKYC!$E:$W,8,0),"") | G18: =IFERROR(VLOOKUP($B$4,[1]EKYC!$E:$W,9,0),"") | H18: =IFERROR(VLOOKUP($B$4,[1]EKYC!$E:$W,10,0),"") | I18: =IFERROR(VLOOKUP($B$4,[1]EKYC!$E:$W,11,0),"") | J18: =IFERROR(VLOOKUP($B$4,[1]EKYC!$E:$W,12,0),"") | K18: =IFERROR(VLOOKUP($B$4,[1]EKYC!$E:$W,13,0),"") | L18: =IFERROR(VLOOKUP($B$4,[1]EKYC!$E:$W,14,0),"") | M18: =IFERROR(VLOOKUP($B$4,[1]EKYC!$E:$W,15,0),"") | N18: =IFERROR(VLOOKUP($B$4,[1]EKYC!$E:$W,16,0),"") | O18: =IFERROR(SUM(C18:N18),"") -> 0 | P18: =IFERROR(O18/$P$26,"") | Q18: =IFERROR($P$26*30,"") -> 0 | R18: =Q18-O18 -> 0 | S18: =O18/($P$26*30) -> #DIV/0! | T18: =IFERROR(IF(S18>=90%,"Outstanding",IF(S18>=80%,"Excellent",IF(S18>=70%,"Very Good",IF(S18>=60%,"Good",IF(S18>=50%,"Average",IF(S18>=40%,"Below Average",IF(S18>=30%,"Poor",IF(S18>=20%,"Very Poor",IF(S18<=20%,"Not Satisfactory"))))))))),"")
B19: APY | C19: =IFERROR(VLOOKUP($B$4,[1]APY!$F:$X,5,0),"") | D19: =IFERROR(VLOOKUP($B$4,[1]APY!$F:$X,6,0),"") | E19: =IFERROR(VLOOKUP($B$4,[1]APY!$F:$X,7,0),"") | F19: =IFERROR(VLOOKUP($B$4,[1]APY!$F:$X,8,0),"") | G19: =IFERROR(VLOOKUP($B$4,[1]APY!$F:$X,9,0),"") | H19: =IFERROR(VLOOKUP($B$4,[1]APY!$F:$X,10,0),"") | I19: =IFERROR(VLOOKUP($B$4,[1]APY!$F:$X,11,0),"") | J19: =IFERROR(VLOOKUP($B$4,[1]APY!$F:$X,12,0),"") | K19: =IFERROR(VLOOKUP($B$4,[1]APY!$F:$X,13,0),"") | L19: =IFERROR(VLOOKUP($B$4,[1]APY!$F:$X,14,0),"") | M19: =IFERROR(VLOOKUP($B$4,[1]APY!$F:$X,15,0),"") | N19: =IFERROR(VLOOKUP($B$4,[1]APY!$F:$X,16,0),"") | O19: =IFERROR(SUM(C19:N19),"") -> 0 | P19: =IFERROR(O19/$P$26,"") | Q19: =$P$26*15 -> 0 | R19: =Q19-O19 -> 0 | S19: =O19/($P$26*15) -> #DIV/0! | T19: =IFERROR(IF(S19>=90%,"Outstanding",IF(S19>=80%,"Excellent",IF(S19>=70%,"Very Good",IF(S19>=60%,"Good",IF(S19>=50%,"Average",IF(S19>=40%,"Below Average",IF(S19>=30%,"Poor",IF(S19>=20%,"Very Poor",IF(S19<=20%,"Not Satisfactory"))))))))),"")
B20: PMJJBY | C20: =IFERROR(VLOOKUP($B$4,[1]PMJJBY!$F:$X,5,0),"") | D20: =IFERROR(VLOOKUP($B$4,[1]PMJJBY!$F:$X,6,0),"") | E20: =IFERROR(VLOOKUP($B$4,[1]PMJJBY!$F:$X,7,0),"") | F20: =IFERROR(VLOOKUP($B$4,[1]PMJJBY!$F:$X,8,0),"") | G20: =IFERROR(VLOOKUP($B$4,[1]PMJJBY!$F:$X,9,0),"") | H20: =IFERROR(VLOOKUP($B$4,[1]PMJJBY!$F:$X,10,0),"") | I20: =IFERROR(VLOOKUP($B$4,[1]PMJJBY!$F:$X,11,0),"") | J20: =IFERROR(VLOOKUP($B$4,[1]PMJJBY!$F:$X,12,0),"") | K20: =IFERROR(VLOOKUP($B$4,[1]PMJJBY!$F:$X,13,0),"") | L20: =IFERROR(VLOOKUP($B$4,[1]PMJJBY!$F:$X,14,0),"") | M20: =IFERROR(VLOOKUP($B$4,[1]PMJJBY!$F:$X,15,0),"") | N20: =IFERROR(VLOOKUP($B$4,[1]PMJJBY!$F:$X,16,0),"") | O20: =IFERROR(SUM(C20:N20),"") -> 0 | P20: =IFERROR(O20/$P$26,"") | Q20: =$P$26*12 -> 0 | R20: =Q20-O20 -> 0 | S20: =O20/($P$26*12) -> #DIV/0! | T20: =IFERROR(IF(S20>=90%,"Outstanding",IF(S20>=80%,"Excellent",IF(S20>=70%,"Very Good",IF(S20>=60%,"Good",IF(S20>=50%,"Average",IF(S20>=40%,"Below Average",IF(S20>=30%,"Poor",IF(S20>=20%,"Very Poor",IF(S20<=20%,"Not Satisfactory"))))))))),"")
B21: PMSBY | C21: =IFERROR(VLOOKUP($B$4,[1]PMSBY!$F:$X,5,0),"") | D21: =IFERROR(VLOOKUP($B$4,[1]PMSBY!$F:$X,6,0),"") | E21: =IFERROR(VLOOKUP($B$4,[1]PMSBY!$F:$X,7,0),"") | F21: =IFERROR(VLOOKUP($B$4,[1]PMSBY!$F:$X,8,0),"") | G21: =IFERROR(VLOOKUP($B$4,[1]PMSBY!$F:$X,9,0),"") | H21: =IFERROR(VLOOKUP($B$4,[1]PMSBY!$F:$X,10,0),"") | I21: =IFERROR(VLOOKUP($B$4,[1]PMSBY!$F:$X,11,0),"") | J21: =IFERROR(VLOOKUP($B$4,[1]PMSBY!$F:$X,12,0),"") | K21: =IFERROR(VLOOKUP($B$4,[1]PMSBY!$F:$X,13,0),"") | L21: =IFERROR(VLOOKUP($B$4,[1]PMSBY!$F:$X,14,0),"") | M21: =IFERROR(VLOOKUP($B$4,[1]PMSBY!$F:$X,15,0),"") | N21: =IFERROR(VLOOKUP($B$4,[1]PMSBY!$F:$X,16,0),"") | O21: =IFERROR(SUM(C21:N21),"") -> 0 | P21: =IFERROR(O21/$P$26,"") | Q21: =$P$26*24 -> 0 | R21: =Q21-O21 -> 0 | S21: =O21/($P$26*24) -> #DIV/0! | T21: =IFERROR(IF(S21>=90%,"Outstanding",IF(S21>=80%,"Excellent",IF(S21>=70%,"Very Good",IF(S21>=60%,"Good",IF(S21>=50%,"Average",IF(S21>=40%,"Below Average",IF(S21>=30%,"Poor",IF(S21>=20%,"Very Poor",IF(S21<=20%,"Not Satisfactory"))))))))),"")
B22: Daily LogIn | C22: =IFERROR(VLOOKUP($B$4,[1]EKYC!$E:$W,5,0),"") | D22: =IFERROR(VLOOKUP($B$4,[1]EKYC!$E:$W,6,0),"") | E22: =IFERROR(VLOOKUP($B$4,[1]EKYC!$E:$W,7,0),"") | F22: =IFERROR(VLOOKUP($B$4,[1]EKYC!$E:$W,8,0),"") | G22: =IFERROR(VLOOKUP($B$4,[1]EKYC!$E:$W,9,0),"") | H22: =IFERROR(VLOOKUP($B$4,[1]EKYC!$E:$W,10,0),"") | I22: =IFERROR(VLOOKUP($B$4,[1]EKYC!$E:$W,11,0),"") | J22: =IFERROR(VLOOKUP($B$4,[1]EKYC!$E:$W,12,0),"") | K22: =IFERROR(VLOOKUP($B$4,[1]EKYC!$E:$W,13,0),"") | L22: =IFERROR(VLOOKUP($B$4,[1]EKYC!$E:$W,14,0),"") | M22: =IFERROR(VLOOKUP($B$4,[1]EKYC!$E:$W,15,0),"") | N22: =IFERROR(VLOOKUP($B$4,[1]EKYC!$E:$W,16,0),"") | O22: =IFERROR(SUM(C22:N22),"") -> 0 | P22: =IFERROR(O22/$P$26,"") | Q22: Monthly Target: AC -30, APY - 15, PMJJBY - 12, PMSBY - 24
B23: Transaction | C23: =IFERROR(VLOOKUP($B$4,[1]TXN!$E:$U,3,0),"") | D23: =IFERROR(VLOOKUP($B$4,[1]TXN!$E:$U,4,0),"") | E23: =IFERROR(VLOOKUP($B$4,[1]TXN!$E:$U,5,0),"") | F23: =IFERROR(VLOOKUP($B$4,[1]TXN!$E:$U,6,0),"") | G23: =IFERROR(VLOOKUP($B$4,[1]TXN!$E:$U,7,0),"") | H23: =IFERROR(VLOOKUP($B$4,[1]TXN!$E:$U,8,0),"") | I23: =IFERROR(VLOOKUP($B$4,[1]TXN!$E:$U,9,0),"") | J23: =IFERROR(VLOOKUP($B$4,[1]TXN!$E:$U,10,0),"") | K23: =IFERROR(VLOOKUP($B$4,[1]TXN!$E:$U,11,0),"") | L23: =IFERROR(VLOOKUP($B$4,[1]TXN!$E:$U,12,0),"") | M23: =IFERROR(VLOOKUP($B$4,[1]TXN!$E:$U,13,0),"") | N23: =IFERROR(VLOOKUP($B$4,[1]TXN!$E:$U,14,0),"") | O23: =IFERROR(SUM(C23:N23),"") -> 0 | P23: =IFERROR(O23/$P$26,"")
B24: Commission | C24: =IFERROR(C26*80%,"") | D24: =IFERROR(D26*80%,"") | E24: =IFERROR(E26*80%,"") | F24: =IFERROR(F26*80%,"") | G24: =IFERROR(G26*80%,"") | H24: =IFERROR(H26*80%,"") | I24: =IFERROR(I26*80%,"") | J24: =IFERROR(J26*80%,"") | ... N24: =IFERROR(N26*80%,"") | O24: =IFERROR(SUM(C24:N24),"") -> 0 | P24: =IFERROR(O24/$P$26,"")
B26: Commission | C26: =IFERROR(VLOOKUP($B$4,[1]COMM!$E:$V,4,0),"") | D26: =IFERROR(VLOOKUP($B$4,[1]COMM!$E:$V,5,0),"") | E26: =IFERROR(VLOOKUP($B$4,[1]COMM!$E:$V,6,0),"") | F26: =IFERROR(VLOOKUP($B$4,[1]COMM!$E:$V,7,0),"") | G26: =IFERROR(VLOOKUP($B$4,[1]COMM!$E:$V,8,0),"") | H26: =IFERROR(VLOOKUP($B$4,[1]COMM!$E:$V,9,0),"") | I26: =IFERROR(VLOOKUP($B$4,[1]COMM!$E:$V,10,0),"") | J26: =IFERROR(VLOOKUP($B$4,[1]COMM!$E:$V,11,0),"") | K26: =IFERROR(VLOOKUP($B$4,[1]COMM!$E:$V,12,0),"") | L26: =IFERROR(VLOOKUP($B$4,[1]COMM!$E:$V,13,0),"") | M26: =IFERROR(VLOOKUP($B$4,[1]COMM!$E:$V,14,0),"") | N26: =IFERROR(VLOOKUP($B$4,[1]COMM!$E:$V,15,0),"") | O26: =SUM(C26:N26) -> 0 | P26: =COUNTIF(C26:N26,">0") -> 0
B27: FY 2024-25
B28: Category | C28: 45383 | D28: 45413 | E28: 45444 | F28: 45474 | G28: 45505 | H28: 45536 | I28: 45566 | J28: 45597 | K28: 45627 | L28: 45658 | M28: 45689 | N28: 45717 | O28: Total | P28: Average | Q28: Target | R28: Gap | S28: % | T28: Performance
B29: PMJDY AC | C29: =IFERROR(VLOOKUP($B$4,[2]AC!$G:$W,4,0),"") | D29: =IFERROR(VLOOKUP($B$4,[2]AC!$G:$W,5,0),"") | E29: =IFERROR(VLOOKUP($B$4,[2]AC!$G:$W,6,0),"") | F29: =IFERROR(VLOOKUP($B$4,[2]AC!$G:$W,7,0),"") | G29: =IFERROR(VLOOKUP($B$4,[2]AC!$G:$W,8,0),"") | H29: =IFERROR(VLOOKUP($B$4,[2]AC!$G:$W,9,0),"") | I29: =IFERROR(VLOOKUP($B$4,[2]AC!$G:$W,10,0),"") | J29: =IFERROR(VLOOKUP($B$4,[2]AC!$G:$W,11,0),"") | K29: =IFERROR(VLOOKUP($B$4,[2]AC!$G:$W,12,0),"") | L29: =IFERROR(VLOOKUP($B$4,[2]AC!$G:$W,13,0),"") | M29: =IFERROR(VLOOKUP($B$4,[2]AC!$G:$W,14,0),"") | N29: =IFERROR(VLOOKUP($B$4,[2]AC!$G:$W,15,0),"") | O29: =IFERROR(SUM(C29:N29),"") -> 0 | P29: =IFERROR(O29/$P$37,"") | Q29: =$P$37*30 -> 0 | R29: =Q29-O29 -> 0 | S29: =O29/($P$37*30) -> #DIV/0! | T29: =IFERROR(IF(S29>=90%,"Outstanding",IF(S29>=80%,"Excellent",IF(S29>=70%,"Very Good",IF(S29>=60%,"Good",IF(S29>=50%,"Average",IF(S29>=40%,"Below Average",IF(S29>=30%,"Poor",IF(S29>=20%,"Very Poor",IF(S29<=20%,"Not Satisfactory"))))))))),"")
B30: APY | C30: =IFERROR(VLOOKUP($B$4,[2]APY!$G:$X,5,0),"") | D30: =IFERROR(VLOOKUP($B$4,[2]APY!$G:$X,6,0),"") | E30: =IFERROR(VLOOKUP($B$4,[2]APY!$G:$X,7,0),"") | F30: =IFERROR(VLOOKUP($B$4,[2]APY!$G:$X,8,0),"") | G30: =IFERROR(VLOOKUP($B$4,[2]APY!$G:$X,9,0),"") | H30: =IFERROR(VLOOKUP($B$4,[2]APY!$G:$X,10,0),"") | I30: =IFERROR(VLOOKUP($B$4,[2]APY!$G:$X,11,0),"") | J30: =IFERROR(VLOOKUP($B$4,[2]APY!$G:$X,12,0),"") | K30: =IFERROR(VLOOKUP($B$4,[2]APY!$G:$X,13,0),"") | L30: =IFERROR(VLOOKUP($B$4,[2]APY!$G:$X,14,0),"") | M30: =IFERROR(VLOOKUP($B$4,[2]APY!$G:$X,15,0),"") | N30: =IFERROR(VLOOKUP($B$4,[2]APY!$G:$X,16,0),"") | O30: =IFERROR(SUM(C30:N30),"") -> 0 | P30: =IFERROR(O30/$P$37,"") | Q30: =$P$37*15 -> 0 | R30: =Q30-O30 -> 0 | S30: =O30/($P$37*15) -> #DIV/0! | T30: =IFERROR(IF(S30>=90%,"Outstanding",IF(S30>=80%,"Excellent",IF(S30>=70%,"Very Good",IF(S30>=60%,"Good",IF(S30>=50%,"Average",IF(S30>=40%,"Below Average",IF(S30>=30%,"Poor",IF(S30>=20%,"Very Poor",IF(S30<=20%,"Not Satisfactory"))))))))),"")
B31: PMJJBY | C31: =IFERROR(VLOOKUP($B$4,[2]JJBY!$G:$X,5,0),"") | D31: =IFERROR(VLOOKUP($B$4,[2]JJBY!$G:$X,6,0),"") | E31: =IFERROR(VLOOKUP($B$4,[2]JJBY!$G:$X,7,0),"") | F31: =IFERROR(VLOOKUP($B$4,[2]JJBY!$G:$X,8,0),"") | G31: =IFERROR(VLOOKUP($B$4,[2]JJBY!$G:$X,9,0),"") | H31: =IFERROR(VLOOKUP($B$4,[2]JJBY!$G:$X,10,0),"") | I31: =IFERROR(VLOOKUP($B$4,[2]JJBY!$G:$X,11,0),"") | J31: =IFERROR(VLOOKUP($B$4,[2]JJBY!$G:$X,12,0),"") | K31: =IFERROR(VLOOKUP($B$4,[2]JJBY!$G:$X,13,0),"") | L31: =IFERROR(VLOOKUP($B$4,[2]JJBY!$G:$X,14,0),"") | M31: =IFERROR(VLOOKUP($B$4,[2]JJBY!$G:$X,15,0),"") | N31: =IFERROR(VLOOKUP($B$4,[2]JJBY!$G:$X,16,0),"") | O31: =IFERROR(SUM(C31:N31),"") -> 0 | P31: =IFERROR(O31/$P$37,"") | Q31: =$P$37*12 -> 0 | R31: =Q31-O31 -> 0 | S31: =O31/($P$37*12) -> #DIV/0! | T31: =IFERROR(IF(S31>=90%,"Outstanding",IF(S31>=80%,"Excellent",IF(S31>=70%,"Very Good",IF(S31>=60%,"Good",IF(S31>=50%,"Average",IF(S31>=40%,"Below Average",IF(S31>=30%,"Poor",IF(S31>=20%,"Very Poor",IF(S31<=20%,"Not Satisfactory"))))))))),"")
B32: PMSBY | C32: =IFERROR(VLOOKUP($B$4,[2]SBY!$G:$X,5,0),"") | D32: =IFERROR(VLOOKUP($B$4,[2]SBY!$G:$X,6,0),"") | E32: =IFERROR(VLOOKUP($B$4,[2]SBY!$G:$X,7,0),"") | F32: =IFERROR(VLOOKUP($B$4,[2]SBY!$G:$X,8,0),"") | G32: =IFERROR(VLOOKUP($B$4,[2]SBY!$G:$X,9,0),"") | H32: =IFERROR(VLOOKUP($B$4,[2]SBY!$G:$X,10,0),"") | I32: =IFERROR(VLOOKUP($B$4,[2]SBY!$G:$X,11,0),"") | J32: =IFERROR(VLOOKUP($B$4,[2]SBY!$G:$X,12,0),"") | K32: =IFERROR(VLOOKUP($B$4,[2]SBY!$G:$X,13,0),"") | L32: =IFERROR(VLOOKUP($B$4,[2]SBY!$G:$X,14,0),"") | M32: =IFERROR(VLOOKUP($B$4,[2]SBY!$G:$X,15,0),"") | N32: =IFERROR(VLOOKUP($B$4,[2]SBY!$G:$X,16,0),"") | O32: =IFERROR(SUM(C32:N32),"") -> 0 | P32: =IFERROR(O32/$P$37,"") | Q32: =$P$37*24 -> 0 | R32: =Q32-O32 -> 0 | S32: =O32/($P$37*24) -> #DIV/0! | T32: =IFERROR(IF(S32>=90%,"Outstanding",IF(S32>=80%,"Excellent",IF(S32>=70%,"Very Good",IF(S32>=60%,"Good",IF(S32>=50%,"Average",IF(S32>=40%,"Below Average",IF(S32>=30%,"Poor",IF(S32>=20%,"Very Poor",IF(S32<=20%,"Not Satisfactory"))))))))),"")
B33: Daily LogIn | C33: =IFERROR(VLOOKUP($B$4,[2]Log!$G:$V,3,0),"") | D33: =IFERROR(VLOOKUP($B$4,[2]Log!$G:$V,4,0),"") | F33: =IFERROR(VLOOKUP($B$4,[2]Log!$G:$V,6,0),"") | G33: =IFERROR(VLOOKUP($B$4,[2]Log!$G:$V,7,0),"") | H33: =IFERROR(VLOOKUP($B$4,[2]Log!$G:$V,8,0),"") | I33: =IFERROR(VLOOKUP($B$4,[2]Log!$G:$V,9,0),"") | J33: =IFERROR(VLOOKUP($B$4,[2]Log!$G:$V,10,0),"") | K33: =IFERROR(VLOOKUP($B$4,[2]Log!$G:$V,11,0),"") | L33: =IFERROR(VLOOKUP($B$4,[2]Log!$G:$V,12,0),"") | M33: =IFERROR(VLOOKUP($B$4,[2]Log!$G:$V,13,0),"") | N33: =IFERROR(VLOOKUP($B$4,[2]Log!$G:$V,14,0),"") | O33: =SUM(C33:N33) -> 0 | P33: =IFERROR(O33/$P$37,"") | Q33: Monthly Target: AC -30, APY - 15, PMJJBY - 12, PMSBY - 24
B34: Transaction | C34: =IFERROR(VLOOKUP($B$4,'[2]FI txn'!$G:$W,3,0),"") | D34: =IFERROR(VLOOKUP($B$4,'[2]FI txn'!$G:$W,4,0),"") | E34: =IFERROR(VLOOKUP($B$4,'[2]FI txn'!$G:$W,5,0),"") | F34: =IFERROR(VLOOKUP($B$4,'[2]FI txn'!$G:$W,6,0),"") | G34: =IFERROR(VLOOKUP($B$4,'[2]FI txn'!$G:$W,7,0),"") | H34: =IFERROR(VLOOKUP($B$4,'[2]FI txn'!$G:$W,8,0),"") | I34: =IFERROR(VLOOKUP($B$4,'[2]FI txn'!$G:$W,9,0),"") | J34: =IFERROR(VLOOKUP($B$4,'[2]FI txn'!$G:$W,10,0),"") | K34: =IFERROR(VLOOKUP($B$4,'[2]FI txn'!$G:$W,11,0),"") | L34: =IFERROR(VLOOKUP($B$4,'[2]FI txn'!$G:$W,12,0),"") | M34: =IFERROR(VLOOKUP($B$4,'[2]FI txn'!$G:$W,13,0),"") | N34: =IFERROR(VLOOKUP($B$4,'[2]FI txn'!$G:$W,14,0),"") | O34: =SUM(C34:N34) -> 0 | P34: =IFERROR(O34/$P$37,"")
B35: Commission | C35: =IFERROR(C37*80%,"") | D35: =IFERROR(D37*80%,"") | E35: =IFERROR(E37*80%,"") | F35: =IFERROR(F37*80%,"") | G35: =IFERROR(G37*80%,"") | H35: =IFERROR(H37*80%,"") | I35: =IFERROR(I37*80%,"") | J35: =IFERROR(J37*80%,"") | ... N35: =IFERROR(N37*80%,"") | O35: =IFERROR(SUM(C35:N35),"") -> 0 | P35: =IFERROR(O35/$P$37,"")
B37: Commission | C37: =IFERROR(VLOOKUP($B$4,[2]Comm!$G:$W,4,0),"") | D37: =IFERROR(VLOOKUP($B$4,[2]Comm!$G:$W,5,0),"") | E37: =IFERROR(VLOOKUP($B$4,[2]Comm!$G:$W,6,0),"") | F37: =IFERROR(VLOOKUP($B$4,[2]Comm!$G:$W,7,0),"") | G37: =IFERROR(VLOOKUP($B$4,[2]Comm!$G:$W,8,0),"") | H37: =IFERROR(VLOOKUP($B$4,[2]Comm!$G:$W,9,0),"") | I37: =IFERROR(VLOOKUP($B$4,[2]Comm!$G:$W,10,0),"") | J37: =IFERROR(VLOOKUP($B$4,[2]Comm!$G:$W,11,0),"") | K37: =IFERROR(VLOOKUP($B$4,[2]Comm!$G:$W,12,0),"") | L37: =IFERROR(VLOOKUP($B$4,[2]Comm!$G:$W,13,0),"") | M37: =IFERROR(VLOOKUP($B$4,[2]Comm!$G:$W,14,0),"") | N37: =IFERROR(VLOOKUP($B$4,[2]Comm!$G:$W,15,0),"") | O37: =SUM(C37:N37) -> 0 | P37: =COUNTIF(C37:N37,">0") -> 0

Sheet ZO Wise
B2: UCO Bank: Performance Summarized FY 2026-27 | Q2: till - | R2: =TODAY()-1 -> 46271
B3: ZO Name | C3: Total Code | D3: Active Code | E3: Inactive Code | F3: Category | G3: 46113 | H3: 46143 | I3: 46174 | J3: 46204 | K3: 46235 | L3: 46266 | M3: 46296 | N3: 46327 | O3: 46357 | P3: 46388 | Q3: 46419 | R3: 46447 | S3: Total
B4: Siliguri | C4: =D4+E4 -> 29 | D4: =VLOOKUP($B$4,'Z Code'!$A:$D,2,0) -> 21 | E4: =VLOOKUP($B$4,'Z Code'!$A:$D,3,0) -> 8 | F4: Account | G4: =VLOOKUP($B$4,'Z AC'!$A:$N,2,0) -> 213 | H4: =VLOOKUP($B$4,'Z AC'!$A:$N,3,0) -> 333 | I4: =VLOOKUP($B$4,'Z AC'!$A:$N,4,0) -> 380 | J4: =VLOOKUP($B$4,'Z AC'!$A:$N,5,0) -> 451 | K4: =VLOOKUP($B$4,'Z AC'!$A:$N,6,0) -> 323 | L4: =VLOOKUP($B$4,'Z AC'!$A:$N,7,0) -> 71 | M4: =VLOOKUP($B$4,'Z AC'!$A:$N,8,0) -> 0 | N4: =VLOOKUP($B$4,'Z AC'!$A:$N,9,0) -> 0 | O4: =VLOOKUP($B$4,'Z AC'!$A:$N,10,0) -> 0 | P4: =VLOOKUP($B$4,'Z AC'!$A:$N,11,0) -> 0 | Q4: =VLOOKUP($B$4,'Z AC'!$A:$N,12,0) -> 0 | R4: =VLOOKUP($B$4,'Z AC'!$A:$N,13,0) -> 0 | S4: =SUM(G4:R4) -> 1771 | U4: =I4/$C$4 -> 13.103448
F5: APY | G5: =VLOOKUP($B$4,'Z APY'!$A:$N,2,0) -> 8 | H5: =VLOOKUP($B$4,'Z APY'!$A:$N,3,0) -> 6 | I5: =VLOOKUP($B$4,'Z APY'!$A:$N,4,0) -> 24 | J5: =VLOOKUP($B$4,'Z APY'!$A:$N,5,0) -> 39 | K5: =VLOOKUP($B$4,'Z APY'!$A:$N,6,0) -> 41 | L5: =VLOOKUP($B$4,'Z APY'!$A:$N,7,0) -> 3 | M5: =VLOOKUP($B$4,'Z APY'!$A:$N,8,0) -> 0 | N5: =VLOOKUP($B$4,'Z APY'!$A:$N,9,0) -> 0 | O5: =VLOOKUP($B$4,'Z APY'!$A:$N,10,0) -> 0 | P5: =VLOOKUP($B$4,'Z APY'!$A:$N,11,0) -> 0 | Q5: =VLOOKUP($B$4,'Z APY'!$A:$N,12,0) -> 0 | R5: =VLOOKUP($B$4,'Z APY'!$A:$N,13,0) -> 0 | S5: =SUM(G5:R5) -> 121 | U5: =I5/$C$4 -> 0.82758621
F6: PMJJBY | G6: =VLOOKUP($B$4,'Z JJBY'!$A:$N,2,0) -> 40 | H6: =VLOOKUP($B$4,'Z JJBY'!$A:$N,3,0) -> 35 | I6: =VLOOKUP($B$4,'Z JJBY'!$A:$N,4,0) -> 31 | J6: =VLOOKUP($B$4,'Z JJBY'!$A:$N,5,0) -> 29 | K6: =VLOOKUP($B$4,'Z JJBY'!$A:$N,6,0) -> 20 | L6: =VLOOKUP($B$4,'Z JJBY'!$A:$N,7,0) -> 4 | M6: =VLOOKUP($B$4,'Z JJBY'!$A:$N,8,0) -> 0 | N6: =VLOOKUP($B$4,'Z JJBY'!$A:$N,9,0) -> 0 | O6: =VLOOKUP($B$4,'Z JJBY'!$A:$N,10,0) -> 0 | P6: =VLOOKUP($B$4,'Z JJBY'!$A:$N,11,0) -> 0 | Q6: =VLOOKUP($B$4,'Z JJBY'!$A:$N,12,0) -> 0 | R6: =VLOOKUP($B$4,'Z JJBY'!$A:$N,13,0) -> 0 | S6: =SUM(G6:R6) -> 159 | U6: =I6/$C$4 -> 1.0689655
F7: PMSBY | G7: =VLOOKUP($B$4,'Z SBY'!$A:$N,2,0) -> 141 | H7: =VLOOKUP($B$4,'Z SBY'!$A:$N,3,0) -> 206 | I7: =VLOOKUP($B$4,'Z SBY'!$A:$N,4,0) -> 214 | J7: =VLOOKUP($B$4,'Z SBY'!$A:$N,5,0) -> 290 | K7: =VLOOKUP($B$4,'Z SBY'!$A:$N,6,0) -> 201 | L7: =VLOOKUP($B$4,'Z SBY'!$A:$N,7,0) -> 43 | M7: =VLOOKUP($B$4,'Z SBY'!$A:$N,8,0) -> 0 | N7: =VLOOKUP($B$4,'Z SBY'!$A:$N,9,0) -> 0 | O7: =VLOOKUP($B$4,'Z SBY'!$A:$N,10,0) -> 0 | P7: =VLOOKUP($B$4,'Z SBY'!$A:$N,11,0) -> 0 | Q7: =VLOOKUP($B$4,'Z SBY'!$A:$N,12,0) -> 0 | R7: =VLOOKUP($B$4,'Z SBY'!$A:$N,13,0) -> 0 | S7: =SUM(G7:R7) -> 1095 | U7: =I7/$C$4 -> 7.3793103
B9: UCO Bank: Performance Summarized FY 2026-27 | Q9: till - | R9: =R2 -> 46271
B10: ZO Name | C10: Total Code | D10: Active Code | E10: Inactive Code | F10: Category | G10: 46113 | H10: 46143 | I10: 46174 | J10: 46204 | K10: 46235 | L10: 46266 | M10: 46296 | N10: 46327 | O10: 46357 | P10: 46388 | Q10: 46419 | R10: 46447 | S10: Total
B11: Durgapur | C11: =D11+E11 -> 26 | D11: =VLOOKUP($B$11,'Z Code'!$A:$D,2,0) -> 16 | E11: =VLOOKUP($B$11,'Z Code'!$A:$D,3,0) -> 10 | F11: Account | G11: =VLOOKUP($B$11,'Z AC'!$A:$N,2,0) -> 186 | H11: =VLOOKUP($B$11,'Z AC'!$A:$N,3,0) -> 577 | I11: =VLOOKUP($B$11,'Z AC'!$A:$N,4,0) -> 296 | J11: =VLOOKUP($B$11,'Z AC'!$A:$N,5,0) -> 426 | K11: =VLOOKUP($B$11,'Z AC'!$A:$N,6,0) -> 265 | L11: =VLOOKUP($B$11,'Z AC'!$A:$N,7,0) -> 44 | M11: =VLOOKUP($B$11,'Z AC'!$A:$N,8,0) -> 0 | N11: =VLOOKUP($B$11,'Z AC'!$A:$N,9,0) -> 0 | O11: =VLOOKUP($B$11,'Z AC'!$A:$N,10,0) -> 0 | P11: =VLOOKUP($B$11,'Z AC'!$A:$N,11,0) -> 0 | Q11: =VLOOKUP($B$11,'Z AC'!$A:$N,12,0) -> 0 | R11: =VLOOKUP($B$11,'Z AC'!$A:$N,13,0) -> 0 | S11: =SUM(G11:R11) -> 1794
F12: APY | G12: =VLOOKUP($B$11,'Z APY'!$A:$N,2,0) -> 9 | H12: =VLOOKUP($B$11,'Z APY'!$A:$N,3,0) -> 13 | I12: =VLOOKUP($B$11,'Z APY'!$A:$N,4,0) -> 29 | J12: =VLOOKUP($B$11,'Z APY'!$A:$N,5,0) -> 16 | K12: =VLOOKUP($B$11,'Z APY'!$A:$N,6,0) -> 43 | L12: =VLOOKUP($B$11,'Z APY'!$A:$N,7,0) -> 6 | M12: =VLOOKUP($B$11,'Z APY'!$A:$N,8,0) -> 0 | N12: =VLOOKUP($B$11,'Z APY'!$A:$N,9,0) -> 0 | O12: =VLOOKUP($B$11,'Z APY'!$A:$N,10,0) -> 0 | P12: =VLOOKUP($B$11,'Z APY'!$A:$N,11,0) -> 0 | Q12: =VLOOKUP($B$11,'Z APY'!$A:$N,12,0) -> 0 | R12: =VLOOKUP($B$11,'Z APY'!$A:$N,13,0) -> 0 | S12: =SUM(G12:R12) -> 116
F13: PMJJBY | G13: =VLOOKUP($B$11,'Z JJBY'!$A:$N,2,0) -> 72 | H13: =VLOOKUP($B$11,'Z JJBY'!$A:$N,3,0) -> 186 | I13: =VLOOKUP($B$11,'Z JJBY'!$A:$N,4,0) -> 40 | J13: =VLOOKUP($B$11,'Z JJBY'!$A:$N,5,0) -> 67 | K13: =VLOOKUP($B$11,'Z JJBY'!$A:$N,6,0) -> 37 | L13: =VLOOKUP($B$11,'Z JJBY'!$A:$N,7,0) -> 6 | M13: =VLOOKUP($B$11,'Z JJBY'!$A:$N,8,0) -> 0 | N13: =VLOOKUP($B$11,'Z JJBY'!$A:$N,9,0) -> 0 | O13: =VLOOKUP($B$11,'Z JJBY'!$A:$N,10,0) -> 0 | P13: =VLOOKUP($B$11,'Z JJBY'!$A:$N,11,0) -> 0 | Q13: =VLOOKUP($B$11,'Z JJBY'!$A:$N,12,0) -> 0 | R13: =VLOOKUP($B$11,'Z JJBY'!$A:$N,13,0) -> 0 | S13: =SUM(G13:R13) -> 408
F14: PMSBY | G14: =VLOOKUP($B$11,'Z SBY'!$A:$N,2,0) -> 124 | H14: =VLOOKUP($B$11,'Z SBY'!$A:$N,3,0) -> 437 | I14: =VLOOKUP($B$11,'Z SBY'!$A:$N,4,0) -> 201 | J14: =VLOOKUP($B$11,'Z SBY'!$A:$N,5,0) -> 267 | K14: =VLOOKUP($B$11,'Z SBY'!$A:$N,6,0) -> 196 | L14: =VLOOKUP($B$11,'Z SBY'!$A:$N,7,0) -> 29 | M14: =VLOOKUP($B$11,'Z SBY'!$A:$N,8,0) -> 0 | N14: =VLOOKUP($B$11,'Z SBY'!$A:$N,9,0) -> 0 | O14: =VLOOKUP($B$11,'Z SBY'!$A:$N,10,0) -> 0 | P14: =VLOOKUP($B$11,'Z SBY'!$A:$N,11,0) -> 0 | Q14: =VLOOKUP($B$11,'Z SBY'!$A:$N,12,0) -> 0 | R14: =VLOOKUP($B$11,'Z SBY'!$A:$N,13,0) -> 0 | S14: =SUM(G14:R14) -> 1254
B16: UCO Bank: Performance Summarized FY 2026-27 | Q16: till - | R16: =R2 -> 46271
B17: ZO Name | C17: Total Code | D17: Active Code | E17: Inactive Code | F17: Category | G17: 46113 | H17: 46143 | I17: 46174 | J17: 46204 | K17: 46235 | L17: 46266 | M17: 46296 | N17: 46327 | O17: 46357 | P17: 46388 | Q17: 46419 | R17: 46447 | S17: Total
B18: Hooghly | C18: =D18+E18 -> 47 | D18: =VLOOKUP($B$18,'Z Code'!$A:$D,2,0) -> 41 | E18: =VLOOKUP($B$18,'Z Code'!$A:$D,3,0) -> 6 | F18: Account | G18: =VLOOKUP($B$18,'Z AC'!$A:$N,2,0) -> 188 | H18: =VLOOKUP($B$18,'Z AC'!$A:$N,3,0) -> 522 | I18: =VLOOKUP($B$18,'Z AC'!$A:$N,4,0) -> 455 | J18: =VLOOKUP($B$18,'Z AC'!$A:$N,5,0) -> 463 | K18: =VLOOKUP($B$18,'Z AC'!$A:$N,6,0) -> 347 | L18: =VLOOKUP($B$18,'Z AC'!$A:$N,7,0) -> 48 | M18: =VLOOKUP($B$18,'Z AC'!$A:$N,8,0) -> 0 | N18: =VLOOKUP($B$18,'Z AC'!$A:$N,9,0) -> 0 | O18: =VLOOKUP($B$18,'Z AC'!$A:$N,10,0) -> 0 | P18: =VLOOKUP($B$18,'Z AC'!$A:$N,11,0) -> 0 | Q18: =VLOOKUP($B$18,'Z AC'!$A:$N,12,0) -> 0 | R18: =VLOOKUP($B$18,'Z AC'!$A:$N,13,0) -> 0 | S18: =SUM(G18:R18) -> 2023
F19: APY | G19: =VLOOKUP($B$18,'Z APY'!$A:$N,2,0) -> 21 | H19: =VLOOKUP($B$18,'Z APY'!$A:$N,3,0) -> 80 | I19: =VLOOKUP($B$18,'Z APY'!$A:$N,4,0) -> 47 | J19: =VLOOKUP($B$18,'Z APY'!$A:$N,5,0) -> 73 | K19: =VLOOKUP($B$18,'Z APY'!$A:$N,6,0) -> 90 | L19: =VLOOKUP($B$18,'Z APY'!$A:$N,7,0) -> 17 | M19: =VLOOKUP($B$18,'Z APY'!$A:$N,8,0) -> 0 | N19: =VLOOKUP($B$18,'Z APY'!$A:$N,9,0) -> 0 | O19: =VLOOKUP($B$18,'Z APY'!$A:$N,10,0) -> 0 | P19: =VLOOKUP($B$18,'Z APY'!$A:$N,11,0) -> 0 | Q19: =VLOOKUP($B$18,'Z APY'!$A:$N,13,0) -> 0 | R19: =VLOOKUP($B$18,'Z APY'!$A:$N,13,0) -> 0 | S19: =SUM(G19:R19) -> 328
F20: PMJJBY | G20: =VLOOKUP($B$18,'Z JJBY'!$A:$N,2,0) -> 101 | H20: =VLOOKUP($B$18,'Z JJBY'!$A:$N,3,0) -> 205 | I20: =VLOOKUP($B$18,'Z JJBY'!$A:$N,4,0) -> 146 | J20: =VLOOKUP($B$18,'Z JJBY'!$A:$N,5,0) -> 143 | K20: =VLOOKUP($B$18,'Z JJBY'!$A:$N,6,0) -> 167 | L20: =VLOOKUP($B$18,'Z JJBY'!$A:$N,7,0) -> 36 | M20: =VLOOKUP($B$18,'Z JJBY'!$A:$N,8,0) -> 0 | N20: =VLOOKUP($B$18,'Z JJBY'!$A:$N,9,0) -> 0 | O20: =VLOOKUP($B$18,'Z JJBY'!$A:$N,10,0) -> 0 | P20: =VLOOKUP($B$18,'Z JJBY'!$A:$N,11,0) -> 0 | Q20: =VLOOKUP($B$18,'Z JJBY'!$A:$N,12,0) -> 0 | R20: =VLOOKUP($B$18,'Z JJBY'!$A:$N,13,0) -> 0 | S20: =SUM(G20:R20) -> 798
F21: PMSBY | G21: =VLOOKUP($B$18,'Z SBY'!$A:$N,2,0) -> 179 | H21: =VLOOKUP($B$18,'Z SBY'!$A:$N,3,0) -> 492 | I21: =VLOOKUP($B$18,'Z SBY'!$A:$N,4,0) -> 346 | J21: =VLOOKUP($B$18,'Z SBY'!$A:$N,5,0) -> 355 | K21: =VLOOKUP($B$18,'Z SBY'!$A:$N,6,0) -> 299 | L21: =VLOOKUP($B$18,'Z SBY'!$A:$N,7,0) -> 52 | M21: =VLOOKUP($B$18,'Z SBY'!$A:$N,8,0) -> 0 | N21: =VLOOKUP($B$18,'Z SBY'!$A:$N,9,0) -> 0 | O21: =VLOOKUP($B$18,'Z SBY'!$A:$N,10,0) -> 0 | P21: =VLOOKUP($B$18,'Z SBY'!$A:$N,11,0) -> 0 | Q21: =VLOOKUP($B$18,'Z SBY'!$A:$N,12,0) -> 0 | R21: =VLOOKUP($B$18,'Z SBY'!$A:$N,13,0) -> 0 | S21: =SUM(G21:R21) -> 1723
B23: UCO Bank: Performance Summarized FY 2026-27 | Q23: till - | R23: =R2 -> 46271
B24: ZO Name | C24: Total Code | D24: Active Code | E24: Inactive Code | F24: Category | G24: 46113 | H24: 46143 | I24: 46174 | J24: 46204 | K24: 46235 | L24: 46266 | M24: 46296 | N24: 46327 | O24: 46357 | P24: 46388 | Q24: 46419 | R24: 46447 | S24: Total
B25: Saltlake | C25: =D25+E25 -> 1 | D25: =VLOOKUP($B$25,'Z Code'!$A:$D,2,0) -> 1 | E25: =VLOOKUP($B$25,'Z Code'!$A:$D,3,0) -> 0 | F25: Account | G25: =VLOOKUP($B$25,'Z AC'!$A:$N,2,0) -> 0 | H25: =VLOOKUP($B$25,'Z AC'!$A:$N,3,0) -> 0 | I25: =VLOOKUP($B$25,'Z AC'!$A:$N,4,0) -> 0 | J25: =VLOOKUP($B$25,'Z AC'!$A:$N,5,0) -> 0 | K25: =VLOOKUP($B$25,'Z AC'!$A:$N,6,0) -> 0 | L25: =VLOOKUP($B$25,'Z AC'!$A:$N,7,0) -> 1 | M25: =VLOOKUP($B$25,'Z AC'!$A:$N,8,0) -> 0 | N25: =VLOOKUP($B$25,'Z AC'!$A:$N,9,0) -> 0 | O25: =VLOOKUP($B$25,'Z AC'!$A:$N,10,0) -> 0 | P25: =VLOOKUP($B$25,'Z AC'!$A:$N,11,0) -> 0 | Q25: =VLOOKUP($B$25,'Z AC'!$A:$N,12,0) -> 0 | R25: =VLOOKUP($B$25,'Z AC'!$A:$N,13,0) -> 0 | S25: =SUM(G25:R25) -> 1
F26: APY | G26: =VLOOKUP($B$25,'Z APY'!$A:$N,2,0) -> 0 | H26: =VLOOKUP($B$25,'Z APY'!$A:$N,3,0) -> 0 | I26: =VLOOKUP($B$25,'Z APY'!$A:$N,4,0) -> 0 | J26: =VLOOKUP($B$25,'Z APY'!$A:$N,5,0) -> 0 | K26: =VLOOKUP($B$25,'Z APY'!$A:$N,6,0) -> 0 | L26: =VLOOKUP($B$25,'Z APY'!$A:$N,7,0) -> 0 | M26: =VLOOKUP($B$25,'Z APY'!$A:$N,8,0) -> 0 | N26: =VLOOKUP($B$25,'Z APY'!$A:$N,9,0) -> 0 | O26: =VLOOKUP($B$25,'Z APY'!$A:$N,10,0) -> 0 | P26: =VLOOKUP($B$25,'Z APY'!$A:$N,11,0) -> 0 | Q26: =VLOOKUP($B$25,'Z APY'!$A:$N,12,0) -> 0 | R26: =VLOOKUP($B$25,'Z APY'!$A:$N,13,0) -> 0 | S26: =SUM(G26:R26) -> 0
F27: PMJJBY | G27: =VLOOKUP($B$25,'Z JJBY'!$A:$N,2,0) -> 0 | H27: =VLOOKUP($B$25,'Z JJBY'!$A:$N,3,0) -> 0 | I27: =VLOOKUP($B$25,'Z JJBY'!$A:$N,4,0) -> 0 | J27: =VLOOKUP($B$25,'Z JJBY'!$A:$N,5,0) -> 0 | K27: =VLOOKUP($B$25,'Z JJBY'!$A:$N,6,0) -> 0 | L27: =VLOOKUP($B$25,'Z JJBY'!$A:$N,7,0) -> 0 | M27: =VLOOKUP($B$25,'Z JJBY'!$A:$N,8,0) -> 0 | N27: =VLOOKUP($B$25,'Z JJBY'!$A:$N,9,0) -> 0 | O27: =VLOOKUP($B$25,'Z JJBY'!$A:$N,10,0) -> 0 | P27: =VLOOKUP($B$25,'Z JJBY'!$A:$N,11,0) -> 0 | Q27: =VLOOKUP($B$25,'Z JJBY'!$A:$N,12,0) -> 0 | R27: =VLOOKUP($B$25,'Z JJBY'!$A:$N,13,0) -> 0 | S27: =SUM(G27:R27) -> 0
F28: PMSBY | G28: =VLOOKUP($B$25,'Z SBY'!$A:$N,2,0) -> 0 | H28: =VLOOKUP($B$25,'Z SBY'!$A:$N,3,0) -> 0 | I28: =VLOOKUP($B$25,'Z SBY'!$A:$N,4,0) -> 0 | J28: =VLOOKUP($B$25,'Z SBY'!$A:$N,5,0) -> 0 | K28: =VLOOKUP($B$25,'Z SBY'!$A:$N,6,0) -> 0 | L28: =VLOOKUP($B$25,'Z SBY'!$A:$N,7,0) -> 0 | M28: =VLOOKUP($B$25,'Z SBY'!$A:$N,8,0) -> 0 | N28: =VLOOKUP($B$25,'Z SBY'!$A:$N,9,0) -> 0 | O28: =VLOOKUP($B$25,'Z SBY'!$A:$N,10,0) -> 0 | P28: =VLOOKUP($B$25,'Z SBY'!$A:$N,11,0) -> 0 | Q28: =VLOOKUP($B$25,'Z SBY'!$A:$N,12,0) -> 0 | R28: =VLOOKUP($B$25,'Z SBY'!$A:$N,13,0) -> 0 | S28: =SUM(G28:R28) -> 0
B30: UCO Bank: Performance Summarized FY 2026-27 | Q30: till - | R30: =R2 -> 46271
B31: Total | C31: Total Code | D31: Active Code | E31: Inactive Code | F31: Category | G31: 46113 | H31: 46143 | I31: 46174 | J31: 46204 | K31: 46235 | L31: 46266 | M31: 46296 | N31: 46327 | O31: 46357 | P31: 46388 | Q31: 46419 | R31: 46447 | S31: Total
B32: West Bengal | C32: =C4+C11+C18 -> 102 | D32: =D4+D11+D18 -> 78 | E32: =E4+E11+E18 -> 24 | F32: Account | G32: =G4+G11+G18+G25 -> 587 | H32: =H4+H11+H18+H25 -> 1432 | I32: =I4+I11+I18+I25 -> 1131 | J32: =J4+J11+J18+J25 -> 1340 | K32: =K4+K11+K18+K25 -> 935 | L32: =L4+L11+L18+L25 -> 164 | M32: =M4+M11+M18+M25 -> 0 | N32: =N4+N11+N18+N25 -> 0 | ... R32: =R4+R11+R18+R25 -> 0 | S32: =SUM(G32:R32) -> 5589
F33: APY | G33: =G5+G12+G19+G26 -> 38 | H33: =H5+H12+H19+H26 -> 99 | I33: =I5+I12+I19+I26 -> 100 | J33: =J5+J12+J19+J26 -> 128 | K33: =K5+K12+K19+K26 -> 174 | L33: =L5+L12+L19+L26 -> 26 | M33: =M5+M12+M19+M26 -> 0 | N33: =N5+N12+N19+N26 -> 0 | ... R33: =R5+R12+R19+R26 -> 0 | S33: =SUM(G33:R33) -> 565
F34: PMJJBY | G34: =G6+G13+G20+G27 -> 213 | H34: =H6+H13+H20+H27 -> 426 | I34: =I6+I13+I20+I27 -> 217 | J34: =J6+J13+J20+J27 -> 239 | K34: =K6+K13+K20+K27 -> 224 | L34: =L6+L13+L20+L27 -> 46 | M34: =M6+M13+M20+M27 -> 0 | N34: =N6+N13+N20+N27 -> 0 | ... R34: =R6+R13+R20+R27 -> 0 | S34: =SUM(G34:R34) -> 1365
F35: PMSBY | G35: =G7+G14+G21+G28 -> 444 | H35: =H7+H14+H21+H28 -> 1135 | I35: =I7+I14+I21+I28 -> 761 | J35: =J7+J14+J21+J28 -> 912 | K35: =K7+K14+K21+K28 -> 696 | L35: =L7+L14+L21+L28 -> 124 | M35: =M7+M14+M21+M28 -> 0 | N35: =N7+N14+N21+N28 -> 0 | ... R35: =R7+R14+R21+R28 -> 0 | S35: =SUM(G35:R35) -> 4072
B37: Category | C37: Code | D37: Active Code | E37: Inactive Code | F37: AC | G37: APY | H37: JJBY | I37: SBY
B38: Total --> | C38: =C4+C11+C18+C25 -> 103 | D38: =D4+D11+D18+D25 -> 79 | E38: =E4+E11+E18+E25 -> 24 | F38: =S4+S11+S18+S25 -> 5589 | G38: =S5+S12+S19+S26 -> 565 | H38: =S6+S13+S20+S27 -> 1365 | I38: =S7+S14+S21+S28 -> 4072
B39: Siliguri | C39: =C4/$C$38 -> 0.2815534 | D39: =D4/D38 -> 0.26582278 | E39: =E4/E38 -> 0.33333333 | F39: =S4/F38 -> 0.31687243 | G39: =S5/G38 -> 0.21415929 | H39: =S6/H38 -> 0.11648352 | I39: =S7/I38 -> 0.26890963
B40: Durgapur | C40: =C11/C38 -> 0.25242718 | D40: =D11/D38 -> 0.20253165 | E40: =E11/E38 -> 0.41666667 | F40: =S11/F38 -> 0.32098765 | G40: =S12/G38 -> 0.20530973 | H40: =S13/H38 -> 0.2989011 | I40: =S14/I38 -> 0.30795678
B41: Hooghly | C41: =C18/C38 -> 0.45631068 | D41: =D18/D38 -> 0.51898734 | E41: =E18/E38 -> 0.25 | F41: =S18/F38 -> 0.36196099 | G41: =S19/G38 -> 0.58053097 | H41: =S20/H38 -> 0.58461538 | I41: =S21/I38 -> 0.4231336

Sheet DC Sum
B2: ACCOUNT: DC Wise Summary FY 2026-27 (UCO Bank) | W2: ACCOUNT: DC Wise Paticipants Summary FY 2026-27 (UCO Bank)
B3: Sl No | C3: DC Name | D3: Target | E3: 46113 | F3: 46143 | G3: 46174 | H3: 46204 | I3: 46235 | J3: 46266 | K3: 46296 | L3: 46327 | M3: 46357 | N3: 46388 | O3: 46419 | P3: 46447 | Q3: Total Account | R3: % of Achievement | W3: Sl No | X3: DC Name | Y3: 46113 | Z3: 46143 | AA3: 46174 | AB3: 46204 | AC3: 46235 | AD3: 46266 | AE3: 46296 | AF3: 46327 | AG3: 46357 | AH3: 46388 | AI3: 46419 | AJ3: 46447 | AK3: Total Count
B4: =ROW()-ROW($B$3) -> 1 | C4: Shyamalesh Sarkar | D4: =VLOOKUP(C4,'AC Pivot'!$A:$O,2,0) -> 540 | E4: =VLOOKUP(C4,'AC Pivot'!$A:$O,3,0) -> 66 | F4: =VLOOKUP(C4,'AC Pivot'!$A:$O,4,0) -> 81 | G4: =VLOOKUP(C4,'AC Pivot'!$A:$O,5,0) -> 104 | H4: =VLOOKUP(C4,'AC Pivot'!$A:$O,6,0) -> 142 | I4: =VLOOKUP(C4,'AC Pivot'!$A:$O,7,0) -> 69 | J4: =VLOOKUP(C4,'AC Pivot'!$A:$O,8,0) -> 10 | K4: =VLOOKUP(C4,'AC Pivot'!$A:$O,9,0) -> 0 | L4: =VLOOKUP(C4,'AC Pivot'!$A:$O,10,0) -> 0 | M4: =VLOOKUP(C4,'AC Pivot'!$A:$O,11,0) -> 0 | N4: =VLOOKUP(C4,'AC Pivot'!$A:$O,12,0) -> 0 | O4: =VLOOKUP(C4,'AC Pivot'!$A:$O,13,0) -> 0 | P4: =VLOOKUP(C4,'AC Pivot'!$A:$O,14,0) -> 0 | Q4: =SUM(E4:P4) -> 472 | R4: =Q4/D4 -> 0.87407407 | W4: =ROW()-ROW($B$3) -> 1 | X4: =C4 -> Shyamalesh Sarkar | Y4: =VLOOKUP(X4,'AC Pivot'!$Q:$AD,2,0) -> 3 | Z4: =VLOOKUP(X4,'AC Pivot'!$Q:$AD,3,0) -> 3 | AA4: =VLOOKUP(X4,'AC Pivot'!$Q:$AD,4,0) -> 3 | AB4: =VLOOKUP(X4,'AC Pivot'!$Q:$AD,5,0) -> 3 | AC4: =VLOOKUP(X4,'AC Pivot'!$Q:$AD,6,0) -> 3 | AD4: =VLOOKUP(X4,'AC Pivot'!$Q:$AD,7,0) -> 3 | AE4: =VLOOKUP(X4,'AC Pivot'!$Q:$AD,8,0) -> 0 | AF4: =VLOOKUP(X4,'AC Pivot'!$Q:$AD,9,0) -> 0 | AG4: =VLOOKUP(X4,'AC Pivot'!$Q:$AD,10,0) -> 0 | AH4: =VLOOKUP(X4,'AC Pivot'!$Q:$AD,11,0) -> 0 | AI4: =VLOOKUP(X4,'AC Pivot'!$Q:$AD,12,0) -> 0 | AJ4: =VLOOKUP(X4,'AC Pivot'!$Q:$AD,13,0) -> 0 | AK4: =VLOOKUP(X4,'AC Pivot'!$Q:$AD,14,0) -> 3
B5: =ROW()-ROW($B$3) -> 2 | C5: Chandi Charan Mahato | D5: =VLOOKUP(C5,'AC Pivot'!$A:$O,2,0) -> 840 | E5: =VLOOKUP(C5,'AC Pivot'!$A:$O,3,0) -> 81 | F5: =VLOOKUP(C5,'AC Pivot'!$A:$O,4,0) -> 145 | G5: =VLOOKUP(C5,'AC Pivot'!$A:$O,5,0) -> 81 | H5: =VLOOKUP(C5,'AC Pivot'!$A:$O,6,0) -> 92 | I5: =VLOOKUP(C5,'AC Pivot'!$A:$O,7,0) -> 89 | J5: =VLOOKUP(C5,'AC Pivot'!$A:$O,8,0) -> 10 | K5: =VLOOKUP(C5,'AC Pivot'!$A:$O,9,0) -> 0 | L5: =VLOOKUP(C5,'AC Pivot'!$A:$O,10,0) -> 0 | M5: =VLOOKUP(C5,'AC Pivot'!$A:$O,11,0) -> 0 | N5: =VLOOKUP(C5,'AC Pivot'!$A:$O,12,0) -> 0 | O5: =VLOOKUP(C5,'AC Pivot'!$A:$O,13,0) -> 0 | P5: =VLOOKUP(C5,'AC Pivot'!$A:$O,14,0) -> 0 | Q5: =SUM(E5:P5) -> 498 | R5: =Q5/D5 -> 0.59285714 | W5: =ROW()-ROW($B$3) -> 2 | X5: =C5 -> Chandi Charan Mahato | Y5: =VLOOKUP(X5,'AC Pivot'!$Q:$AD,2,0) -> 4 | Z5: =VLOOKUP(X5,'AC Pivot'!$Q:$AD,3,0) -> 5 | AA5: =VLOOKUP(X5,'AC Pivot'!$Q:$AD,4,0) -> 4 | AB5: =VLOOKUP(X5,'AC Pivot'!$Q:$AD,5,0) -> 4 | AC5: =VLOOKUP(X5,'AC Pivot'!$Q:$AD,6,0) -> 4 | AD5: =VLOOKUP(X5,'AC Pivot'!$Q:$AD,7,0) -> 3 | AE5: =VLOOKUP(X5,'AC Pivot'!$Q:$AD,8,0) -> 0 | AF5: =VLOOKUP(X5,'AC Pivot'!$Q:$AD,9,0) -> 0 | AG5: =VLOOKUP(X5,'AC Pivot'!$Q:$AD,10,0) -> 0 | AH5: =VLOOKUP(X5,'AC Pivot'!$Q:$AD,11,0) -> 0 | AI5: =VLOOKUP(X5,'AC Pivot'!$Q:$AD,12,0) -> 0 | AJ5: =VLOOKUP(X5,'AC Pivot'!$Q:$AD,13,0) -> 0 | AK5: =VLOOKUP(X5,'AC Pivot'!$Q:$AD,14,0) -> 5
B6: =ROW()-ROW($B$3) -> 3 | C6: Pijush Singha | D6: =VLOOKUP(C6,'AC Pivot'!$A:$O,2,0) -> 360 | E6: =VLOOKUP(C6,'AC Pivot'!$A:$O,3,0) -> 25 | F6: =VLOOKUP(C6,'AC Pivot'!$A:$O,4,0) -> 50 | G6: =VLOOKUP(C6,'AC Pivot'!$A:$O,5,0) -> 24 | H6: =VLOOKUP(C6,'AC Pivot'!$A:$O,6,0) -> 47 | I6: =VLOOKUP(C6,'AC Pivot'!$A:$O,7,0) -> 33 | J6: =VLOOKUP(C6,'AC Pivot'!$A:$O,8,0) -> 9 | K6: =VLOOKUP(C6,'AC Pivot'!$A:$O,9,0) -> 0 | L6: =VLOOKUP(C6,'AC Pivot'!$A:$O,10,0) -> 0 | M6: =VLOOKUP(C6,'AC Pivot'!$A:$O,11,0) -> 0 | N6: =VLOOKUP(C6,'AC Pivot'!$A:$O,12,0) -> 0 | O6: =VLOOKUP(C6,'AC Pivot'!$A:$O,13,0) -> 0 | P6: =VLOOKUP(C6,'AC Pivot'!$A:$O,14,0) -> 0 | Q6: =SUM(E6:P6) -> 188 | R6: =Q6/D6 -> 0.52222222 | W6: =ROW()-ROW($B$3) -> 3 | X6: =C6 -> Pijush Singha | Y6: =VLOOKUP(X6,'AC Pivot'!$Q:$AD,2,0) -> 2 | Z6: =VLOOKUP(X6,'AC Pivot'!$Q:$AD,3,0) -> 2 | AA6: =VLOOKUP(X6,'AC Pivot'!$Q:$AD,4,0) -> 2 | AB6: =VLOOKUP(X6,'AC Pivot'!$Q:$AD,5,0) -> 2 | AC6: =VLOOKUP(X6,'AC Pivot'!$Q:$AD,6,0) -> 2 | AD6: =VLOOKUP(X6,'AC Pivot'!$Q:$AD,7,0) -> 2 | AE6: =VLOOKUP(X6,'AC Pivot'!$Q:$AD,8,0) -> 0 | AF6: =VLOOKUP(X6,'AC Pivot'!$Q:$AD,9,0) -> 0 | AG6: =VLOOKUP(X6,'AC Pivot'!$Q:$AD,10,0) -> 0 | AH6: =VLOOKUP(X6,'AC Pivot'!$Q:$AD,11,0) -> 0 | AI6: =VLOOKUP(X6,'AC Pivot'!$Q:$AD,12,0) -> 0 | AJ6: =VLOOKUP(X6,'AC Pivot'!$Q:$AD,13,0) -> 0 | AK6: =VLOOKUP(X6,'AC Pivot'!$Q:$AD,14,0) -> 2
B7: =ROW()-ROW($B$3) -> 4 | C7: Sunil Biswas | D7: =VLOOKUP(C7,'AC Pivot'!$A:$O,2,0) -> 2220 | E7: =VLOOKUP(C7,'AC Pivot'!$A:$O,3,0) -> 92 | F7: =VLOOKUP(C7,'AC Pivot'!$A:$O,4,0) -> 386 | G7: =VLOOKUP(C7,'AC Pivot'!$A:$O,5,0) -> 176 | H7: =VLOOKUP(C7,'AC Pivot'!$A:$O,6,0) -> 301 | I7: =VLOOKUP(C7,'AC Pivot'!$A:$O,7,0) -> 137 | J7: =VLOOKUP(C7,'AC Pivot'!$A:$O,8,0) -> 21 | K7: =VLOOKUP(C7,'AC Pivot'!$A:$O,9,0) -> 0 | L7: =VLOOKUP(C7,'AC Pivot'!$A:$O,10,0) -> 0 | M7: =VLOOKUP(C7,'AC Pivot'!$A:$O,11,0) -> 0 | N7: =VLOOKUP(C7,'AC Pivot'!$A:$O,12,0) -> 0 | O7: =VLOOKUP(C7,'AC Pivot'!$A:$O,13,0) -> 0 | P7: =VLOOKUP(C7,'AC Pivot'!$A:$O,14,0) -> 0 | Q7: =SUM(E7:P7) -> 1113 | R7: =Q7/D7 -> 0.50135135 | W7: =ROW()-ROW($B$3) -> 4 | X7: =C7 -> Sunil Biswas | Y7: =VLOOKUP(X7,'AC Pivot'!$Q:$AD,2,0) -> 13 | Z7: =VLOOKUP(X7,'AC Pivot'!$Q:$AD,3,0) -> 11 | AA7: =VLOOKUP(X7,'AC Pivot'!$Q:$AD,4,0) -> 12 | AB7: =VLOOKUP(X7,'AC Pivot'!$Q:$AD,5,0) -> 13 | AC7: =VLOOKUP(X7,'AC Pivot'!$Q:$AD,6,0) -> 12 | AD7: =VLOOKUP(X7,'AC Pivot'!$Q:$AD,7,0) -> 9 | AE7: =VLOOKUP(X7,'AC Pivot'!$Q:$AD,8,0) -> 0 | AF7: =VLOOKUP(X7,'AC Pivot'!$Q:$AD,9,0) -> 0 | AG7: =VLOOKUP(X7,'AC Pivot'!$Q:$AD,10,0) -> 0 | AH7: =VLOOKUP(X7,'AC Pivot'!$Q:$AD,11,0) -> 0 | AI7: =VLOOKUP(X7,'AC Pivot'!$Q:$AD,12,0) -> 0 | AJ7: =VLOOKUP(X7,'AC Pivot'!$Q:$AD,13,0) -> 0 | AK7: =VLOOKUP(X7,'AC Pivot'!$Q:$AD,14,0) -> 15
B8: =ROW()-ROW($B$3) -> 5 | C8: Sanjoy Paul | D8: =VLOOKUP(C8,'AC Pivot'!$A:$O,2,0) -> 180 | E8: =VLOOKUP(C8,'AC Pivot'!$A:$O,3,0) -> 13 | F8: =VLOOKUP(C8,'AC Pivot'!$A:$O,4,0) -> 20 | G8: =VLOOKUP(C8,'AC Pivot'!$A:$O,5,0) -> 9 | H8: =VLOOKUP(C8,'AC Pivot'!$A:$O,6,0) -> 19 | I8: =VLOOKUP(C8,'AC Pivot'!$A:$O,7,0) -> 14 | J8: =VLOOKUP(C8,'AC Pivot'!$A:$O,8,0) -> 1 | K8: =VLOOKUP(C8,'AC Pivot'!$A:$O,9,0) -> 0 | L8: =VLOOKUP(C8,'AC Pivot'!$A:$O,10,0) -> 0 | M8: =VLOOKUP(C8,'AC Pivot'!$A:$O,11,0) -> 0 | N8: =VLOOKUP(C8,'AC Pivot'!$A:$O,12,0) -> 0 | O8: =VLOOKUP(C8,'AC Pivot'!$A:$O,13,0) -> 0 | P8: =VLOOKUP(C8,'AC Pivot'!$A:$O,14,0) -> 0 | Q8: =SUM(E8:P8) -> 76 | R8: =Q8/D8 -> 0.42222222 | W8: =ROW()-ROW($B$3) -> 5 | X8: =C8 -> Sanjoy Paul | Y8: =VLOOKUP(X8,'AC Pivot'!$Q:$AD,2,0) -> 1 | Z8: =VLOOKUP(X8,'AC Pivot'!$Q:$AD,3,0) -> 1 | AA8: =VLOOKUP(X8,'AC Pivot'!$Q:$AD,4,0) -> 1 | AB8: =VLOOKUP(X8,'AC Pivot'!$Q:$AD,5,0) -> 1 | AC8: =VLOOKUP(X8,'AC Pivot'!$Q:$AD,6,0) -> 1 | AD8: =VLOOKUP(X8,'AC Pivot'!$Q:$AD,7,0) -> 1 | AE8: =VLOOKUP(X8,'AC Pivot'!$Q:$AD,8,0) -> 0 | AF8: =VLOOKUP(X8,'AC Pivot'!$Q:$AD,9,0) -> 0 | AG8: =VLOOKUP(X8,'AC Pivot'!$Q:$AD,10,0) -> 0 | AH8: =VLOOKUP(X8,'AC Pivot'!$Q:$AD,11,0) -> 0 | AI8: =VLOOKUP(X8,'AC Pivot'!$Q:$AD,12,0) -> 0 | AJ8: =VLOOKUP(X8,'AC Pivot'!$Q:$AD,13,0) -> 0 | AK8: =VLOOKUP(X8,'AC Pivot'!$Q:$AD,14,0) -> 1
B9: =ROW()-ROW($B$3) -> 6 | C9: Rajiul Momin | D9: =VLOOKUP(C9,'AC Pivot'!$A:$O,2,0) -> 360 | E9: =VLOOKUP(C9,'AC Pivot'!$A:$O,3,0) -> 18 | F9: =VLOOKUP(C9,'AC Pivot'!$A:$O,4,0) -> 35 | G9: =VLOOKUP(C9,'AC Pivot'!$A:$O,5,0) -> 31 | H9: =VLOOKUP(C9,'AC Pivot'!$A:$O,6,0) -> 34 | I9: =VLOOKUP(C9,'AC Pivot'!$A:$O,7,0) -> 21 | J9: =VLOOKUP(C9,'AC Pivot'!$A:$O,8,0) -> 10 | K9: =VLOOKUP(C9,'AC Pivot'!$A:$O,9,0) -> 0 | L9: =VLOOKUP(C9,'AC Pivot'!$A:$O,10,0) -> 0 | M9: =VLOOKUP(C9,'AC Pivot'!$A:$O,11,0) -> 0 | N9: =VLOOKUP(C9,'AC Pivot'!$A:$O,12,0) -> 0 | O9: =VLOOKUP(C9,'AC Pivot'!$A:$O,13,0) -> 0 | P9: =VLOOKUP(C9,'AC Pivot'!$A:$O,14,0) -> 0 | Q9: =SUM(E9:P9) -> 149 | R9: =Q9/D9 -> 0.41388889 | W9: =ROW()-ROW($B$3) -> 6 | X9: =C9 -> Rajiul Momin | Y9: =VLOOKUP(X9,'AC Pivot'!$Q:$AD,2,0) -> 2 | Z9: =VLOOKUP(X9,'AC Pivot'!$Q:$AD,3,0) -> 2 | AA9: =VLOOKUP(X9,'AC Pivot'!$Q:$AD,4,0) -> 2 | AB9: =VLOOKUP(X9,'AC Pivot'!$Q:$AD,5,0) -> 2 | AC9: =VLOOKUP(X9,'AC Pivot'!$Q:$AD,6,0) -> 2 | AD9: =VLOOKUP(X9,'AC Pivot'!$Q:$AD,7,0) -> 2 | AE9: =VLOOKUP(X9,'AC Pivot'!$Q:$AD,8,0) -> 0 | AF9: =VLOOKUP(X9,'AC Pivot'!$Q:$AD,9,0) -> 0 | AG9: =VLOOKUP(X9,'AC Pivot'!$Q:$AD,10,0) -> 0 | AH9: =VLOOKUP(X9,'AC Pivot'!$Q:$AD,11,0) -> 0 | AI9: =VLOOKUP(X9,'AC Pivot'!$Q:$AD,12,0) -> 0 | AJ9: =VLOOKUP(X9,'AC Pivot'!$Q:$AD,13,0) -> 0 | AK9: =VLOOKUP(X9,'AC Pivot'!$Q:$AD,14,0) -> 2
B10: =ROW()-ROW($B$3) -> 7 | C10: Manindra Nath Barman | D10: =VLOOKUP(C10,'AC Pivot'!$A:$O,2,0) -> 960 | E10: =VLOOKUP(C10,'AC Pivot'!$A:$O,3,0) -> 39 | F10: =VLOOKUP(C10,'AC Pivot'!$A:$O,4,0) -> 66 | G10: =VLOOKUP(C10,'AC Pivot'!$A:$O,5,0) -> 86 | H10: =VLOOKUP(C10,'AC Pivot'!$A:$O,6,0) -> 103 | I10: =VLOOKUP(C10,'AC Pivot'!$A:$O,7,0) -> 87 | J10: =VLOOKUP(C10,'AC Pivot'!$A:$O,8,0) -> 13 | K10: =VLOOKUP(C10,'AC Pivot'!$A:$O,9,0) -> 0 | L10: =VLOOKUP(C10,'AC Pivot'!$A:$O,10,0) -> 0 | M10: =VLOOKUP(C10,'AC Pivot'!$A:$O,11,0) -> 0 | N10: =VLOOKUP(C10,'AC Pivot'!$A:$O,12,0) -> 0 | O10: =VLOOKUP(C10,'AC Pivot'!$A:$O,13,0) -> 0 | P10: =VLOOKUP(C10,'AC Pivot'!$A:$O,14,0) -> 0 | Q10: =SUM(E10:P10) -> 394 | R10: =Q10/D10 -> 0.41041667 | W10: =ROW()-ROW($B$3) -> 7 | X10: =C10 -> Manindra Nath Barman | Y10: =VLOOKUP(X10,'AC Pivot'!$Q:$AD,2,0) -> 3 | Z10: =VLOOKUP(X10,'AC Pivot'!$Q:$AD,3,0) -> 3 | AA10: =VLOOKUP(X10,'AC Pivot'!$Q:$AD,4,0) -> 4 | AB10: =VLOOKUP(X10,'AC Pivot'!$Q:$AD,5,0) -> 6 | AC10: =VLOOKUP(X10,'AC Pivot'!$Q:$AD,6,0) -> 6 | AD10: =VLOOKUP(X10,'AC Pivot'!$Q:$AD,7,0) -> 5 | AE10: =VLOOKUP(X10,'AC Pivot'!$Q:$AD,8,0) -> 0 | AF10: =VLOOKUP(X10,'AC Pivot'!$Q:$AD,9,0) -> 0 | AG10: =VLOOKUP(X10,'AC Pivot'!$Q:$AD,10,0) -> 0 | AH10: =VLOOKUP(X10,'AC Pivot'!$Q:$AD,11,0) -> 0 | AI10: =VLOOKUP(X10,'AC Pivot'!$Q:$AD,12,0) -> 0 | AJ10: =VLOOKUP(X10,'AC Pivot'!$Q:$AD,13,0) -> 0 | AK10: =VLOOKUP(X10,'AC Pivot'!$Q:$AD,14,0) -> 7
B11: =ROW()-ROW($B$3) -> 8 | C11: Under Office (Birbhum) | D11: =VLOOKUP(C11,'AC Pivot'!$A:$O,2,0) -> 1140 | E11: =VLOOKUP(C11,'AC Pivot'!$A:$O,3,0) -> 48 | F11: =VLOOKUP(C11,'AC Pivot'!$A:$O,4,0) -> 71 | G11: =VLOOKUP(C11,'AC Pivot'!$A:$O,5,0) -> 92 | H11: =VLOOKUP(C11,'AC Pivot'!$A:$O,6,0) -> 83 | I11: =VLOOKUP(C11,'AC Pivot'!$A:$O,7,0) -> 85 | J11: =VLOOKUP(C11,'AC Pivot'!$A:$O,8,0) -> 18 | K11: =VLOOKUP(C11,'AC Pivot'!$A:$O,9,0) -> 0 | L11: =VLOOKUP(C11,'AC Pivot'!$A:$O,10,0) -> 0 | M11: =VLOOKUP(C11,'AC Pivot'!$A:$O,11,0) -> 0 | N11: =VLOOKUP(C11,'AC Pivot'!$A:$O,12,0) -> 0 | O11: =VLOOKUP(C11,'AC Pivot'!$A:$O,13,0) -> 0 | P11: =VLOOKUP(C11,'AC Pivot'!$A:$O,14,0) -> 0 | Q11: =SUM(E11:P11) -> 397 | R11: =Q11/D11 -> 0.34824561 | W11: =ROW()-ROW($B$3) -> 8 | X11: =C11 -> Under Office (Birbhum) | Y11: =VLOOKUP(X11,'AC Pivot'!$Q:$AD,2,0) -> 7 | Z11: =VLOOKUP(X11,'AC Pivot'!$Q:$AD,3,0) -> 6 | AA11: =VLOOKUP(X11,'AC Pivot'!$Q:$AD,4,0) -> 6 | AB11: =VLOOKUP(X11,'AC Pivot'!$Q:$AD,5,0) -> 6 | AC11: =VLOOKUP(X11,'AC Pivot'!$Q:$AD,6,0) -> 6 | AD11: =VLOOKUP(X11,'AC Pivot'!$Q:$AD,7,0) -> 5 | AE11: =VLOOKUP(X11,'AC Pivot'!$Q:$AD,8,0) -> 0 | AF11: =VLOOKUP(X11,'AC Pivot'!$Q:$AD,9,0) -> 0 | AG11: =VLOOKUP(X11,'AC Pivot'!$Q:$AD,10,0) -> 0 | AH11: =VLOOKUP(X11,'AC Pivot'!$Q:$AD,11,0) -> 0 | AI11: =VLOOKUP(X11,'AC Pivot'!$Q:$AD,12,0) -> 0 | AJ11: =VLOOKUP(X11,'AC Pivot'!$Q:$AD,13,0) -> 0 | AK11: =VLOOKUP(X11,'AC Pivot'!$Q:$AD,14,0) -> 7
B12: =ROW()-ROW($B$3) -> 9 | C12: Rajendra Kumar Bapari | D12: =VLOOKUP(C12,'AC Pivot'!$A:$O,2,0) -> 540 | E12: =VLOOKUP(C12,'AC Pivot'!$A:$O,3,0) -> 13 | F12: =VLOOKUP(C12,'AC Pivot'!$A:$O,4,0) -> 46 | G12: =VLOOKUP(C12,'AC Pivot'!$A:$O,5,0) -> 39 | H12: =VLOOKUP(C12,'AC Pivot'!$A:$O,6,0) -> 33 | I12: =VLOOKUP(C12,'AC Pivot'!$A:$O,7,0) -> 39 | J12: =VLOOKUP(C12,'AC Pivot'!$A:$O,8,0) -> 13 | K12: =VLOOKUP(C12,'AC Pivot'!$A:$O,9,0) -> 0 | L12: =VLOOKUP(C12,'AC Pivot'!$A:$O,10,0) -> 0 | M12: =VLOOKUP(C12,'AC Pivot'!$A:$O,11,0) -> 0 | N12: =VLOOKUP(C12,'AC Pivot'!$A:$O,12,0) -> 0 | O12: =VLOOKUP(C12,'AC Pivot'!$A:$O,13,0) -> 0 | P12: =VLOOKUP(C12,'AC Pivot'!$A:$O,14,0) -> 0 | Q12: =SUM(E12:P12) -> 183 | R12: =Q12/D12 -> 0.33888889 | W12: =ROW()-ROW($B$3) -> 9 | X12: =C12 -> Rajendra Kumar Bapari | Y12: =VLOOKUP(X12,'AC Pivot'!$Q:$AD,2,0) -> 2 | Z12: =VLOOKUP(X12,'AC Pivot'!$Q:$AD,3,0) -> 3 | AA12: =VLOOKUP(X12,'AC Pivot'!$Q:$AD,4,0) -> 3 | AB12: =VLOOKUP(X12,'AC Pivot'!$Q:$AD,5,0) -> 3 | AC12: =VLOOKUP(X12,'AC Pivot'!$Q:$AD,6,0) -> 3 | AD12: =VLOOKUP(X12,'AC Pivot'!$Q:$AD,7,0) -> 3 | AE12: =VLOOKUP(X12,'AC Pivot'!$Q:$AD,8,0) -> 0 | AF12: =VLOOKUP(X12,'AC Pivot'!$Q:$AD,9,0) -> 0 | AG12: =VLOOKUP(X12,'AC Pivot'!$Q:$AD,10,0) -> 0 | AH12: =VLOOKUP(X12,'AC Pivot'!$Q:$AD,11,0) -> 0 | AI12: =VLOOKUP(X12,'AC Pivot'!$Q:$AD,12,0) -> 0 | AJ12: =VLOOKUP(X12,'AC Pivot'!$Q:$AD,13,0) -> 0 | AK12: =VLOOKUP(X12,'AC Pivot'!$Q:$AD,14,0) -> 3
B13: =ROW()-ROW($B$3) -> 10 | C13: Souvik Maity | D13: =VLOOKUP(C13,'AC Pivot'!$A:$O,2,0) -> 2760 | E13: =VLOOKUP(C13,'AC Pivot'!$A:$O,3,0) -> 78 | F13: =VLOOKUP(C13,'AC Pivot'!$A:$O,4,0) -> 249 | G13: =VLOOKUP(C13,'AC Pivot'!$A:$O,5,0) -> 223 | H13: =VLOOKUP(C13,'AC Pivot'!$A:$O,6,0) -> 211 | I13: =VLOOKUP(C13,'AC Pivot'!$A:$O,7,0) -> 143 | J13: =VLOOKUP(C13,'AC Pivot'!$A:$O,8,0) -> 18 | K13: =VLOOKUP(C13,'AC Pivot'!$A:$O,9,0) -> 0 | L13: =VLOOKUP(C13,'AC Pivot'!$A:$O,10,0) -> 0 | M13: =VLOOKUP(C13,'AC Pivot'!$A:$O,11,0) -> 0 | N13: =VLOOKUP(C13,'AC Pivot'!$A:$O,12,0) -> 0 | O13: =VLOOKUP(C13,'AC Pivot'!$A:$O,13,0) -> 0 | P13: =VLOOKUP(C13,'AC Pivot'!$A:$O,14,0) -> 0 | Q13: =SUM(E13:P13) -> 922 | R13: =Q13/D13 -> 0.33405797 | W13: =ROW()-ROW($B$3) -> 10 | X13: =C13 -> Souvik Maity | Y13: =VLOOKUP(X13,'AC Pivot'!$Q:$AD,2,0) -> 15 | Z13: =VLOOKUP(X13,'AC Pivot'!$Q:$AD,3,0) -> 15 | AA13: =VLOOKUP(X13,'AC Pivot'!$Q:$AD,4,0) -> 14 | AB13: =VLOOKUP(X13,'AC Pivot'!$Q:$AD,5,0) -> 14 | AC13: =VLOOKUP(X13,'AC Pivot'!$Q:$AD,6,0) -> 14 | AD13: =VLOOKUP(X13,'AC Pivot'!$Q:$AD,7,0) -> 8 | AE13: =VLOOKUP(X13,'AC Pivot'!$Q:$AD,8,0) -> 0 | AF13: =VLOOKUP(X13,'AC Pivot'!$Q:$AD,9,0) -> 0 | AG13: =VLOOKUP(X13,'AC Pivot'!$Q:$AD,10,0) -> 0 | AH13: =VLOOKUP(X13,'AC Pivot'!$Q:$AD,11,0) -> 0 | AI13: =VLOOKUP(X13,'AC Pivot'!$Q:$AD,12,0) -> 0 | AJ13: =VLOOKUP(X13,'AC Pivot'!$Q:$AD,13,0) -> 0 | AK13: =VLOOKUP(X13,'AC Pivot'!$Q:$AD,14,0) -> 16
B14: =ROW()-ROW($B$3) -> 11 | C14: Under Office (W Medinipur) | D14: =VLOOKUP(C14,'AC Pivot'!$A:$O,2,0) -> 3420 | E14: =VLOOKUP(C14,'AC Pivot'!$A:$O,3,0) -> 97 | F14: =VLOOKUP(C14,'AC Pivot'!$A:$O,4,0) -> 245 | G14: =VLOOKUP(C14,'AC Pivot'!$A:$O,5,0) -> 204 | H14: =VLOOKUP(C14,'AC Pivot'!$A:$O,6,0) -> 196 | I14: =VLOOKUP(C14,'AC Pivot'!$A:$O,7,0) -> 179 | J14: =VLOOKUP(C14,'AC Pivot'!$A:$O,8,0) -> 28 | K14: =VLOOKUP(C14,'AC Pivot'!$A:$O,9,0) -> 0 | L14: =VLOOKUP(C14,'AC Pivot'!$A:$O,10,0) -> 0 | M14: =VLOOKUP(C14,'AC Pivot'!$A:$O,11,0) -> 0 | N14: =VLOOKUP(C14,'AC Pivot'!$A:$O,12,0) -> 0 | O14: =VLOOKUP(C14,'AC Pivot'!$A:$O,13,0) -> 0 | P14: =VLOOKUP(C14,'AC Pivot'!$A:$O,14,0) -> 0 | Q14: =SUM(E14:P14) -> 949 | R14: =Q14/D14 -> 0.27748538 | W14: =ROW()-ROW($B$3) -> 11 | X14: =C14 -> Under Office (W Medinipur) | Y14: =VLOOKUP(X14,'AC Pivot'!$Q:$AD,2,0) -> 15 | Z14: =VLOOKUP(X14,'AC Pivot'!$Q:$AD,3,0) -> 19 | AA14: =VLOOKUP(X14,'AC Pivot'!$Q:$AD,4,0) -> 18 | AB14: =VLOOKUP(X14,'AC Pivot'!$Q:$AD,5,0) -> 16 | AC14: =VLOOKUP(X14,'AC Pivot'!$Q:$AD,6,0) -> 18 | AD14: =VLOOKUP(X14,'AC Pivot'!$Q:$AD,7,0) -> 12 | AE14: =VLOOKUP(X14,'AC Pivot'!$Q:$AD,8,0) -> 0 | AF14: =VLOOKUP(X14,'AC Pivot'!$Q:$AD,9,0) -> 0 | AG14: =VLOOKUP(X14,'AC Pivot'!$Q:$AD,10,0) -> 0 | AH14: =VLOOKUP(X14,'AC Pivot'!$Q:$AD,11,0) -> 0 | AI14: =VLOOKUP(X14,'AC Pivot'!$Q:$AD,12,0) -> 0 | AJ14: =VLOOKUP(X14,'AC Pivot'!$Q:$AD,13,0) -> 0 | AK14: =VLOOKUP(X14,'AC Pivot'!$Q:$AD,14,0) -> 19
B15: =ROW()-ROW($B$3) -> 12 | C15: Avi Sk | D15: =VLOOKUP(C15,'AC Pivot'!$A:$O,2,0) -> 540 | E15: =VLOOKUP(C15,'AC Pivot'!$A:$O,3,0) -> 4 | F15: =VLOOKUP(C15,'AC Pivot'!$A:$O,4,0) -> 10 | G15: =VLOOKUP(C15,'AC Pivot'!$A:$O,5,0) -> 34 | H15: =VLOOKUP(C15,'AC Pivot'!$A:$O,6,0) -> 23 | I15: =VLOOKUP(C15,'AC Pivot'!$A:$O,7,0) -> 14 | J15: =VLOOKUP(C15,'AC Pivot'!$A:$O,8,0) -> 10 | K15: =VLOOKUP(C15,'AC Pivot'!$A:$O,9,0) -> 0 | L15: =VLOOKUP(C15,'AC Pivot'!$A:$O,10,0) -> 0 | M15: =VLOOKUP(C15,'AC Pivot'!$A:$O,11,0) -> 0 | N15: =VLOOKUP(C15,'AC Pivot'!$A:$O,12,0) -> 0 | O15: =VLOOKUP(C15,'AC Pivot'!$A:$O,13,0) -> 0 | P15: =VLOOKUP(C15,'AC Pivot'!$A:$O,14,0) -> 0 | Q15: =SUM(E15:P15) -> 95 | R15: =Q15/D15 -> 0.17592593 | W15: =ROW()-ROW($B$3) -> 12 | X15: =C15 -> Avi Sk | Y15: =VLOOKUP(X15,'AC Pivot'!$Q:$AD,2,0) -> 2 | Z15: =VLOOKUP(X15,'AC Pivot'!$Q:$AD,3,0) -> 2 | AA15: =VLOOKUP(X15,'AC Pivot'!$Q:$AD,4,0) -> 3 | AB15: =VLOOKUP(X15,'AC Pivot'!$Q:$AD,5,0) -> 3 | AC15: =VLOOKUP(X15,'AC Pivot'!$Q:$AD,6,0) -> 3 | AD15: =VLOOKUP(X15,'AC Pivot'!$Q:$AD,7,0) -> 2 | AE15: =VLOOKUP(X15,'AC Pivot'!$Q:$AD,8,0) -> 0 | AF15: =VLOOKUP(X15,'AC Pivot'!$Q:$AD,9,0) -> 0 | AG15: =VLOOKUP(X15,'AC Pivot'!$Q:$AD,10,0) -> 0 | AH15: =VLOOKUP(X15,'AC Pivot'!$Q:$AD,11,0) -> 0 | AI15: =VLOOKUP(X15,'AC Pivot'!$Q:$AD,12,0) -> 0 | AJ15: =VLOOKUP(X15,'AC Pivot'!$Q:$AD,13,0) -> 0 | AK15: =VLOOKUP(X15,'AC Pivot'!$Q:$AD,14,0) -> 3
... B17: =ROW()-ROW($B$3) -> 14 | C17: Mousumi Sarkar | D17: =VLOOKUP(C17,'AC Pivot'!$A:$O,2,0) -> 60 | E17: =VLOOKUP(C17,'AC Pivot'!$A:$O,3,0) -> 0 | F17: =VLOOKUP(C17,'AC Pivot'!$A:$O,4,0) -> 0 | G17: =VLOOKUP(C17,'AC Pivot'!$A:$O,5,0) -> 0 | H17: =VLOOKUP(C17,'AC Pivot'!$A:$O,6,0) -> 0 | I17: =VLOOKUP(C17,'AC Pivot'!$A:$O,7,0) -> 0 | J17: =VLOOKUP(C17,'AC Pivot'!$A:$O,8,0) -> 1 | K17: =VLOOKUP(C17,'AC Pivot'!$A:$O,9,0) -> 0 | L17: =VLOOKUP(C17,'AC Pivot'!$A:$O,10,0) -> 0 | M17: =VLOOKUP(C17,'AC Pivot'!$A:$O,11,0) -> 0 | N17: =VLOOKUP(C17,'AC Pivot'!$A:$O,12,0) -> 0 | O17: =VLOOKUP(C17,'AC Pivot'!$A:$O,13,0) -> 0 | P17: =VLOOKUP(C17,'AC Pivot'!$A:$O,14,0) -> 0 | Q17: =SUM(E17:P17) -> 1 | R17: =Q17/D17 -> 0.016666667 | W17: =ROW()-ROW($B$3) -> 14 | X17: =C17 -> Mousumi Sarkar | Y17: =VLOOKUP(X17,'AC Pivot'!$Q:$AD,2,0) -> 0 | Z17: =VLOOKUP(X17,'AC Pivot'!$Q:$AD,3,0) -> 0 | AA17: =VLOOKUP(X17,'AC Pivot'!$Q:$AD,4,0) -> 0 | AB17: =VLOOKUP(X17,'AC Pivot'!$Q:$AD,5,0) -> 0 | AC17: =VLOOKUP(X17,'AC Pivot'!$Q:$AD,6,0) -> 0 | AD17: =VLOOKUP(X17,'AC Pivot'!$Q:$AD,7,0) -> 1 | AE17: =VLOOKUP(X17,'AC Pivot'!$Q:$AD,8,0) -> 0 | AF17: =VLOOKUP(X17,'AC Pivot'!$Q:$AD,9,0) -> 0 | AG17: =VLOOKUP(X17,'AC Pivot'!$Q:$AD,10,0) -> 0 | AH17: =VLOOKUP(X17,'AC Pivot'!$Q:$AD,11,0) -> 0 | AI17: =VLOOKUP(X17,'AC Pivot'!$Q:$AD,12,0) -> 0 | AJ17: =VLOOKUP(X17,'AC Pivot'!$Q:$AD,13,0) -> 0 | AK17: =VLOOKUP(X17,'AC Pivot'!$Q:$AD,14,0) -> 1
B19: Grand Total | D19: =SUM(D4:D17) -> 14940 | E19: =SUM(E4:E17) -> 587 | F19: =SUM(F4:F17) -> 1432 | G19: =SUM(G4:G17) -> 1131 | H19: =SUM(H4:H17) -> 1340 | I19: =SUM(I4:I17) -> 935 | J19: =SUM(J4:J17) -> 164 | K19: =SUM(K4:K17) -> 0 | ... Q19: =SUM(Q4:Q17) -> 5589 | R19: =Q19/D19 -> 0.37409639 | W19: Grand Total | Y19: =SUM(Y4:Y17) -> 72 | Z19: =SUM(Z4:Z17) -> 76 | AA19: =SUM(AA4:AA17) -> 76 | AB19: =SUM(AB4:AB17) -> 78 | AC19: =SUM(AC4:AC17) -> 77 | AD19: =SUM(AD4:AD17) -> 58 | AE19: =SUM(AE4:AE17) -> 0 | AF19: =SUM(AF4:AF17) -> 0 | ... AK19: =SUM(AK4:AK17) -> 89
B21: APY: DC Wise Summary FY 2026-27 (UCO Bank) | W21: APY: DC Wise Paticipants Summary FY 2026-27 (UCO Bank)
B22: Sl No | C22: DC Name | D22: Target | E22: 46113 | F22: 46143 | G22: 46174 | H22: 46204 | I22: 46235 | J22: 46266 | K22: 46296 | L22: 46327 | M22: 46357 | N22: 46388 | O22: 46419 | P22: 46447 | Q22: Total APY | R22: % of Achievement | W22: Sl No | X22: DC Name | Y22: 46113 | Z22: 46143 | AA22: 46174 | AB22: 46204 | AC22: 46235 | AD22: 46266 | AE22: 46296 | AF22: 46327 | AG22: 46357 | AH22: 46388 | AI22: 46419 | AJ22: 46447 | AK22: Total Count
B23: =ROW()-ROW($B$22) -> 1 | C23: Rajendra Kumar Bapari | D23: =VLOOKUP(C23,'APY Pivot'!$A:$O,2,0) -> 270 | E23: =VLOOKUP(C23,'APY Pivot'!$A:$O,3,0) -> 4 | F23: =VLOOKUP(C23,'APY Pivot'!$A:$O,4,0) -> 6 | G23: =VLOOKUP(C23,'APY Pivot'!$A:$O,5,0) -> 13 | H23: =VLOOKUP(C23,'APY Pivot'!$A:$O,6,0) -> 10 | I23: =VLOOKUP(C23,'APY Pivot'!$A:$O,7,0) -> 18 | J23: =VLOOKUP(C23,'APY Pivot'!$A:$O,8,0) -> 3 | K23: =VLOOKUP(C23,'APY Pivot'!$A:$O,9,0) -> 0 | L23: =VLOOKUP(C23,'APY Pivot'!$A:$O,10,0) -> 0 | M23: =VLOOKUP(C23,'APY Pivot'!$A:$O,11,0) -> 0 | N23: =VLOOKUP(C23,'APY Pivot'!$A:$O,12,0) -> 0 | O23: =VLOOKUP(C23,'APY Pivot'!$A:$O,13,0) -> 0 | P23: =VLOOKUP(C23,'APY Pivot'!$A:$O,14,0) -> 0 | Q23: =SUM(E23:P23) -> 54 | R23: =Q23/D23 -> 0.2 | W23: =ROW()-ROW($B$22) -> 1 | X23: =C23 -> Rajendra Kumar Bapari | Y23: =VLOOKUP(X23,'APY Pivot'!$Q:$AD,2,0) -> 2 | Z23: =VLOOKUP(X23,'APY Pivot'!$Q:$AD,3,0) -> 2 | AA23: =VLOOKUP(X23,'APY Pivot'!$Q:$AD,4,0) -> 3 | AB23: =VLOOKUP(X23,'APY Pivot'!$Q:$AD,5,0) -> 3 | AC23: =VLOOKUP(X23,'APY Pivot'!$Q:$AD,6,0) -> 3 | AD23: =VLOOKUP(X23,'APY Pivot'!$Q:$AD,7,0) -> 2 | AE23: =VLOOKUP(X23,'APY Pivot'!$Q:$AD,8,0) -> 0 | AF23: =VLOOKUP(X23,'APY Pivot'!$Q:$AD,9,0) -> 0 | AG23: =VLOOKUP(X23,'APY Pivot'!$Q:$AD,10,0) -> 0 | AH23: =VLOOKUP(X23,'APY Pivot'!$Q:$AD,11,0) -> 0 | AI23: =VLOOKUP(X23,'APY Pivot'!$Q:$AD,12,0) -> 0 | AJ23: =VLOOKUP(X23,'APY Pivot'!$Q:$AD,13,0) -> 0 | AK23: =VLOOKUP(X23,'APY Pivot'!$Q:$AD,14,0) -> 3
B24: =ROW()-ROW($B$22) -> 2 | C24: Rajiul Momin | D24: =VLOOKUP(C24,'APY Pivot'!$A:$O,2,0) -> 180 | E24: =VLOOKUP(C24,'APY Pivot'!$A:$O,3,0) -> 0 | F24: =VLOOKUP(C24,'APY Pivot'!$A:$O,4,0) -> 0 | G24: =VLOOKUP(C24,'APY Pivot'!$A:$O,5,0) -> 16 | H24: =VLOOKUP(C24,'APY Pivot'!$A:$O,6,0) -> 5 | I24: =VLOOKUP(C24,'APY Pivot'!$A:$O,7,0) -> 10 | J24: =VLOOKUP(C24,'APY Pivot'!$A:$O,8,0) -> 1 | K24: =VLOOKUP(C24,'APY Pivot'!$A:$O,9,0) -> 0 | L24: =VLOOKUP(C24,'APY Pivot'!$A:$O,10,0) -> 0 | M24: =VLOOKUP(C24,'APY Pivot'!$A:$O,11,0) -> 0 | N24: =VLOOKUP(C24,'APY Pivot'!$A:$O,12,0) -> 0 | O24: =VLOOKUP(C24,'APY Pivot'!$A:$O,13,0) -> 0 | P24: =VLOOKUP(C24,'APY Pivot'!$A:$O,14,0) -> 0 | Q24: =SUM(E24:P24) -> 32 | R24: =Q24/D24 -> 0.17777778 | W24: =ROW()-ROW($B$22) -> 2 | X24: =C24 -> Rajiul Momin | Y24: =VLOOKUP(X24,'APY Pivot'!$Q:$AD,2,0) -> 0 | Z24: =VLOOKUP(X24,'APY Pivot'!$Q:$AD,3,0) -> 0 | AA24: =VLOOKUP(X24,'APY Pivot'!$Q:$AD,4,0) -> 2 | AB24: =VLOOKUP(X24,'APY Pivot'!$Q:$AD,5,0) -> 1 | AC24: =VLOOKUP(X24,'APY Pivot'!$Q:$AD,6,0) -> 1 | AD24: =VLOOKUP(X24,'APY Pivot'!$Q:$AD,7,0) -> 1 | AE24: =VLOOKUP(X24,'APY Pivot'!$Q:$AD,8,0) -> 0 | AF24: =VLOOKUP(X24,'APY Pivot'!$Q:$AD,9,0) -> 0 | AG24: =VLOOKUP(X24,'APY Pivot'!$Q:$AD,10,0) -> 0 | AH24: =VLOOKUP(X24,'APY Pivot'!$Q:$AD,11,0) -> 0 | AI24: =VLOOKUP(X24,'APY Pivot'!$Q:$AD,12,0) -> 0 | AJ24: =VLOOKUP(X24,'APY Pivot'!$Q:$AD,13,0) -> 0 | AK24: =VLOOKUP(X24,'APY Pivot'!$Q:$AD,14,0) -> 2
B25: =ROW()-ROW($B$22) -> 3 | C25: Under Office (W Medinipur) | D25: =VLOOKUP(C25,'APY Pivot'!$A:$O,2,0) -> 1710 | E25: =VLOOKUP(C25,'APY Pivot'!$A:$O,3,0) -> 14 | F25: =VLOOKUP(C25,'APY Pivot'!$A:$O,4,0) -> 49 | G25: =VLOOKUP(C25,'APY Pivot'!$A:$O,5,0) -> 27 | H25: =VLOOKUP(C25,'APY Pivot'!$A:$O,6,0) -> 46 | I25: =VLOOKUP(C25,'APY Pivot'!$A:$O,7,0) -> 46 | J25: =VLOOKUP(C25,'APY Pivot'!$A:$O,8,0) -> 14 | K25: =VLOOKUP(C25,'APY Pivot'!$A:$O,9,0) -> 0 | L25: =VLOOKUP(C25,'APY Pivot'!$A:$O,10,0) -> 0 | M25: =VLOOKUP(C25,'APY Pivot'!$A:$O,11,0) -> 0 | N25: =VLOOKUP(C25,'APY Pivot'!$A:$O,12,0) -> 0 | O25: =VLOOKUP(C25,'APY Pivot'!$A:$O,13,0) -> 0 | P25: =VLOOKUP(C25,'APY Pivot'!$A:$O,14,0) -> 0 | Q25: =SUM(E25:P25) -> 196 | R25: =Q25/D25 -> 0.11461988 | W25: =ROW()-ROW($B$22) -> 3 | X25: =C25 -> Under Office (W Medinipur) | Y25: =VLOOKUP(X25,'APY Pivot'!$Q:$AD,2,0) -> 2 | Z25: =VLOOKUP(X25,'APY Pivot'!$Q:$AD,3,0) -> 5 | AA25: =VLOOKUP(X25,'APY Pivot'!$Q:$AD,4,0) -> 10 | AB25: =VLOOKUP(X25,'APY Pivot'!$Q:$AD,5,0) -> 10 | AC25: =VLOOKUP(X25,'APY Pivot'!$Q:$AD,6,0) -> 12 | AD25: =VLOOKUP(X25,'APY Pivot'!$Q:$AD,7,0) -> 3 | AE25: =VLOOKUP(X25,'APY Pivot'!$Q:$AD,8,0) -> 0 | AF25: =VLOOKUP(X25,'APY Pivot'!$Q:$AD,9,0) -> 0 | AG25: =VLOOKUP(X25,'APY Pivot'!$Q:$AD,10,0) -> 0 | AH25: =VLOOKUP(X25,'APY Pivot'!$Q:$AD,11,0) -> 0 | AI25: =VLOOKUP(X25,'APY Pivot'!$Q:$AD,12,0) -> 0 | AJ25: =VLOOKUP(X25,'APY Pivot'!$Q:$AD,13,0) -> 0 | AK25: =VLOOKUP(X25,'APY Pivot'!$Q:$AD,14,0) -> 18
